[2025-04-23 15:05:50,400] ERROR django.request Internal Server Error: /search_supplier/
Traceback (most recent call last):
  File "L:\oneSource_Live\venv\Lib\site-packages\django\db\backends\base\base.py", line 275, in ensure_connection
    self.connect()
    ~~~~~~~~~~~~^^
  File "L:\oneSource_Live\venv\Lib\site-packages\django\utils\asyncio.py", line 26, in inner
    return func(*args, **kwargs)
  File "L:\oneSource_Live\venv\Lib\site-packages\django\db\backends\base\base.py", line 256, in connect
    self.connection = self.get_new_connection(conn_params)
                      ~~~~~~~~~~~~~~~~~~~~~~~^^^^^^^^^^^^^
  File "L:\oneSource_Live\venv\Lib\site-packages\mssql\base.py", line 368, in get_new_connection
    conn = Database.connect(connstr, **args)
pyodbc.OperationalError: ('08S01', '[08S01] [Microsoft][ODBC Driver 17 for SQL Server]Shared Memory Provider: No process is on the other end of the pipe.\r\n (233) (SQLDriverConnect); [08S01] [Microsoft][ODBC Driver 17 for SQL Server]Communication link failure (233); [08S01] [Microsoft][ODBC Driver 17 for SQL Server]Invalid connection string attribute (0)')

The above exception was the direct cause of the following exception:

Traceback (most recent call last):
  File "L:\oneSource_Live\venv\Lib\site-packages\django\core\handlers\exception.py", line 55, in inner
    response = get_response(request)
  File "L:\oneSource_Live\venv\Lib\site-packages\django\core\handlers\base.py", line 197, in _get_response
    response = wrapped_callback(request, *callback_args, **callback_kwargs)
  File "L:\oneSource_Live\oneSource\STORE\views.py", line 32, in search_supplier
    with connections['readonly_db'].cursor() as cursor:
         ~~~~~~~~~~~~~~~~~~~~~~~~~~~~~~~~~^^
  File "L:\oneSource_Live\venv\Lib\site-packages\django\utils\asyncio.py", line 26, in inner
    return func(*args, **kwargs)
  File "L:\oneSource_Live\venv\Lib\site-packages\django\db\backends\base\base.py", line 316, in cursor
    return self._cursor()
           ~~~~~~~~~~~~^^
  File "L:\oneSource_Live\venv\Lib\site-packages\mssql\base.py", line 261, in _cursor
    conn = super()._cursor()
  File "L:\oneSource_Live\venv\Lib\site-packages\django\db\backends\base\base.py", line 292, in _cursor
    self.ensure_connection()
    ~~~~~~~~~~~~~~~~~~~~~~^^
  File "L:\oneSource_Live\venv\Lib\site-packages\django\utils\asyncio.py", line 26, in inner
    return func(*args, **kwargs)
  File "L:\oneSource_Live\venv\Lib\site-packages\django\db\backends\base\base.py", line 274, in ensure_connection
    with self.wrap_database_errors:
         ^^^^^^^^^^^^^^^^^^^^^^^^^
  File "L:\oneSource_Live\venv\Lib\site-packages\django\db\utils.py", line 91, in __exit__
    raise dj_exc_value.with_traceback(traceback) from exc_value
  File "L:\oneSource_Live\venv\Lib\site-packages\django\db\backends\base\base.py", line 275, in ensure_connection
    self.connect()
    ~~~~~~~~~~~~^^
  File "L:\oneSource_Live\venv\Lib\site-packages\django\utils\asyncio.py", line 26, in inner
    return func(*args, **kwargs)
  File "L:\oneSource_Live\venv\Lib\site-packages\django\db\backends\base\base.py", line 256, in connect
    self.connection = self.get_new_connection(conn_params)
                      ~~~~~~~~~~~~~~~~~~~~~~~^^^^^^^^^^^^^
  File "L:\oneSource_Live\venv\Lib\site-packages\mssql\base.py", line 368, in get_new_connection
    conn = Database.connect(connstr, **args)
django.db.utils.OperationalError: ('08S01', '[08S01] [Microsoft][ODBC Driver 17 for SQL Server]Shared Memory Provider: No process is on the other end of the pipe.\r\n (233) (SQLDriverConnect); [08S01] [Microsoft][ODBC Driver 17 for SQL Server]Communication link failure (233); [08S01] [Microsoft][ODBC Driver 17 for SQL Server]Invalid connection string attribute (0)')
[2025-04-23 15:05:50,414] ERROR django.server "GET /search_supplier/?term= HTTP/1.1" 500 145
