[2025-04-19 16:29:33,428] ERROR custom_logger Error while updating vehicle ID 10010 by taufik.s
Traceback (most recent call last):
  File "L:\oneSource_Live\venv\Lib\site-packages\django\db\backends\utils.py", line 105, in _execute
    return self.cursor.execute(sql, params)
           ~~~~~~~~~~~~~~~~~~~^^^^^^^^^^^^^
  File "L:\oneSource_Live\venv\Lib\site-packages\mssql\base.py", line 677, in execute
    return self.cursor.execute(sql, params)
           ~~~~~~~~~~~~~~~~~~~^^^^^^^^^^^^^
pyodbc.IntegrityError: ('23000', "[23000] [Microsoft][ODBC Driver 17 for SQL Server][SQL Server]Cannot insert the value NULL into column 'qty', table 'oneSource_Live.dbo.vehicle'; column does not allow nulls. UPDATE fails. (515) (SQLExecDirectW); [23000] [Microsoft][ODBC Driver 17 for SQL Server][SQL Server]The statement has been terminated. (3621)")

The above exception was the direct cause of the following exception:

Traceback (most recent call last):
  File "L:\oneSource_Live\oneSource\STORE\views.py", line 177, in edit_vehicle
    form.save()
    ~~~~~~~~~^^
  File "L:\oneSource_Live\venv\Lib\site-packages\django\forms\models.py", line 552, in save
    self.instance.save()
    ~~~~~~~~~~~~~~~~~~^^
  File "L:\oneSource_Live\venv\Lib\site-packages\django\db\models\base.py", line 822, in save
    self.save_base(
    ~~~~~~~~~~~~~~^
        using=using,
        ^^^^^^^^^^^^
    ...<2 lines>...
        update_fields=update_fields,
        ^^^^^^^^^^^^^^^^^^^^^^^^^^^^
    )
    ^
  File "L:\oneSource_Live\venv\Lib\site-packages\django\db\models\base.py", line 909, in save_base
    updated = self._save_table(
        raw,
    ...<4 lines>...
        update_fields,
    )
  File "L:\oneSource_Live\venv\Lib\site-packages\django\db\models\base.py", line 1040, in _save_table
    updated = self._do_update(
        base_qs, using, pk_val, values, update_fields, forced_update
    )
  File "L:\oneSource_Live\venv\Lib\site-packages\django\db\models\base.py", line 1105, in _do_update
    return filtered._update(values) > 0
           ~~~~~~~~~~~~~~~~^^^^^^^^
  File "L:\oneSource_Live\venv\Lib\site-packages\django\db\models\query.py", line 1278, in _update
    return query.get_compiler(self.db).execute_sql(CURSOR)
           ~~~~~~~~~~~~~~~~~~~~~~~~~~~~~~~~~~~~~~~^^^^^^^^
  File "L:\oneSource_Live\venv\Lib\site-packages\django\db\models\sql\compiler.py", line 1990, in execute_sql
    cursor = super().execute_sql(result_type)
  File "L:\oneSource_Live\venv\Lib\site-packages\django\db\models\sql\compiler.py", line 1562, in execute_sql
    cursor.execute(sql, params)
    ~~~~~~~~~~~~~~^^^^^^^^^^^^^
  File "L:\oneSource_Live\venv\Lib\site-packages\django\db\backends\utils.py", line 79, in execute
    return self._execute_with_wrappers(
           ~~~~~~~~~~~~~~~~~~~~~~~~~~~^
        sql, params, many=False, executor=self._execute
        ^^^^^^^^^^^^^^^^^^^^^^^^^^^^^^^^^^^^^^^^^^^^^^^
    )
    ^
  File "L:\oneSource_Live\venv\Lib\site-packages\django\db\backends\utils.py", line 92, in _execute_with_wrappers
    return executor(sql, params, many, context)
  File "L:\oneSource_Live\venv\Lib\site-packages\django\db\backends\utils.py", line 100, in _execute
    with self.db.wrap_database_errors:
         ^^^^^^^^^^^^^^^^^^^^^^^^^^^^
  File "L:\oneSource_Live\venv\Lib\site-packages\django\db\utils.py", line 91, in __exit__
    raise dj_exc_value.with_traceback(traceback) from exc_value
  File "L:\oneSource_Live\venv\Lib\site-packages\django\db\backends\utils.py", line 105, in _execute
    return self.cursor.execute(sql, params)
           ~~~~~~~~~~~~~~~~~~~^^^^^^^^^^^^^
  File "L:\oneSource_Live\venv\Lib\site-packages\mssql\base.py", line 677, in execute
    return self.cursor.execute(sql, params)
           ~~~~~~~~~~~~~~~~~~~^^^^^^^^^^^^^
django.db.utils.IntegrityError: ('23000', "[23000] [Microsoft][ODBC Driver 17 for SQL Server][SQL Server]Cannot insert the value NULL into column 'qty', table 'oneSource_Live.dbo.vehicle'; column does not allow nulls. UPDATE fails. (515) (SQLExecDirectW); [23000] [Microsoft][ODBC Driver 17 for SQL Server][SQL Server]The statement has been terminated. (3621)")
[2025-04-19 16:41:37,104] ERROR custom_logger Vehicle ID 10010 not found for editing by taufik.s
Traceback (most recent call last):
  File "L:\oneSource_Live\venv\Lib\site-packages\django\shortcuts.py", line 86, in get_object_or_404
    return queryset.get(*args, **kwargs)
           ~~~~~~~~~~~~^^^^^^^^^^^^^^^^^
  File "L:\oneSource_Live\venv\Lib\site-packages\django\db\models\query.py", line 649, in get
    raise self.model.DoesNotExist(
        "%s matching query does not exist." % self.model._meta.object_name
    )
STORE.models.Vehicle.DoesNotExist: Vehicle matching query does not exist.

During handling of the above exception, another exception occurred:

Traceback (most recent call last):
  File "L:\oneSource_Live\oneSource\STORE\views.py", line 167, in edit_vehicle
    vehicle = get_object_or_404(Vehicle, id=vehicle_id)
  File "L:\oneSource_Live\venv\Lib\site-packages\django\shortcuts.py", line 88, in get_object_or_404
    raise Http404(
        "No %s matches the given query." % queryset.model._meta.object_name
    )
django.http.response.Http404: No Vehicle matches the given query.
