[2025-05-14 11:02:59,982] ERROR django.request Internal Server Error: /check-in-status/all/
Traceback (most recent call last):
  File "L:\oneSource_Live\venv\Lib\site-packages\django\core\handlers\exception.py", line 55, in inner
    response = get_response(request)
  File "L:\oneSource_Live\venv\Lib\site-packages\django\core\handlers\base.py", line 197, in _get_response
    response = wrapped_callback(request, *callback_args, **callback_kwargs)
  File "L:\oneSource_Live\venv\Lib\site-packages\django\contrib\auth\decorators.py", line 23, in _wrapper_view
    return view_func(request, *args, **kwargs)
  File "L:\oneSource_Live\oneSource\HR\views.py", line 660, in check_in_status_detail
    return render(request, 'hr/daily_check_in_status_detail.html', {
        'active_link': 'daily_check_in',
    ...<14 lines>...
        'full_name_query': full_name_query,
    })
  File "L:\oneSource_Live\venv\Lib\site-packages\django\shortcuts.py", line 25, in render
    content = loader.render_to_string(template_name, context, request, using=using)
  File "L:\oneSource_Live\venv\Lib\site-packages\django\template\loader.py", line 62, in render_to_string
    return template.render(context, request)
           ~~~~~~~~~~~~~~~^^^^^^^^^^^^^^^^^^
  File "L:\oneSource_Live\venv\Lib\site-packages\django\template\backends\django.py", line 61, in render
    return self.template.render(context)
           ~~~~~~~~~~~~~~~~~~~~^^^^^^^^^
  File "L:\oneSource_Live\venv\Lib\site-packages\django\template\base.py", line 171, in render
    return self._render(context)
           ~~~~~~~~~~~~^^^^^^^^^
  File "L:\oneSource_Live\venv\Lib\site-packages\django\template\base.py", line 163, in _render
    return self.nodelist.render(context)
           ~~~~~~~~~~~~~~~~~~~~^^^^^^^^^
  File "L:\oneSource_Live\venv\Lib\site-packages\django\template\base.py", line 1000, in render
    return SafeString("".join([node.render_annotated(context) for node in self]))
                               ~~~~~~~~~~~~~~~~~~~~~^^^^^^^^^
  File "L:\oneSource_Live\venv\Lib\site-packages\django\template\base.py", line 961, in render_annotated
    return self.render(context)
           ~~~~~~~~~~~^^^^^^^^^
  File "L:\oneSource_Live\venv\Lib\site-packages\django\template\loader_tags.py", line 159, in render
    return compiled_parent._render(context)
           ~~~~~~~~~~~~~~~~~~~~~~~^^^^^^^^^
  File "L:\oneSource_Live\venv\Lib\site-packages\django\template\base.py", line 163, in _render
    return self.nodelist.render(context)
           ~~~~~~~~~~~~~~~~~~~~^^^^^^^^^
  File "L:\oneSource_Live\venv\Lib\site-packages\django\template\base.py", line 1000, in render
    return SafeString("".join([node.render_annotated(context) for node in self]))
                               ~~~~~~~~~~~~~~~~~~~~~^^^^^^^^^
  File "L:\oneSource_Live\venv\Lib\site-packages\django\template\base.py", line 961, in render_annotated
    return self.render(context)
           ~~~~~~~~~~~^^^^^^^^^
  File "L:\oneSource_Live\venv\Lib\site-packages\django\template\loader_tags.py", line 65, in render
    result = block.nodelist.render(context)
  File "L:\oneSource_Live\venv\Lib\site-packages\django\template\base.py", line 1000, in render
    return SafeString("".join([node.render_annotated(context) for node in self]))
                               ~~~~~~~~~~~~~~~~~~~~~^^^^^^^^^
  File "L:\oneSource_Live\venv\Lib\site-packages\django\template\base.py", line 961, in render_annotated
    return self.render(context)
           ~~~~~~~~~~~^^^^^^^^^
  File "L:\oneSource_Live\venv\Lib\site-packages\django\template\defaulttags.py", line 479, in render
    url = reverse(view_name, args=args, kwargs=kwargs, current_app=current_app)
  File "L:\oneSource_Live\venv\Lib\site-packages\django\urls\base.py", line 88, in reverse
    return resolver._reverse_with_prefix(view, prefix, *args, **kwargs)
           ~~~~~~~~~~~~~~~~~~~~~~~~~~~~~^^^^^^^^^^^^^^^^^^^^^^^^^^^^^^^
  File "L:\oneSource_Live\venv\Lib\site-packages\django\urls\resolvers.py", line 851, in _reverse_with_prefix
    raise NoReverseMatch(msg)
django.urls.exceptions.NoReverseMatch: Reverse for 'check_in_status_detail' with no arguments not found. 1 pattern(s) tried: ['check\\-in\\-status/(?P<check_in_status>[^/]+)/\\Z']
[2025-05-14 11:03:00,008] ERROR django.server "GET /check-in-status/all/?from_date=2025-05-01&to_date=2025-05-14&branch=Mumbai&department=IT HTTP/1.1" 500 145
[2025-05-14 11:03:14,356] ERROR django.request Internal Server Error: /check-in-status/No/
Traceback (most recent call last):
  File "L:\oneSource_Live\venv\Lib\site-packages\django\core\handlers\exception.py", line 55, in inner
    response = get_response(request)
  File "L:\oneSource_Live\venv\Lib\site-packages\django\core\handlers\base.py", line 197, in _get_response
    response = wrapped_callback(request, *callback_args, **callback_kwargs)
  File "L:\oneSource_Live\venv\Lib\site-packages\django\contrib\auth\decorators.py", line 23, in _wrapper_view
    return view_func(request, *args, **kwargs)
  File "L:\oneSource_Live\oneSource\HR\views.py", line 660, in check_in_status_detail
    return render(request, 'hr/daily_check_in_status_detail.html', {
        'active_link': 'daily_check_in',
    ...<14 lines>...
        'full_name_query': full_name_query,
    })
  File "L:\oneSource_Live\venv\Lib\site-packages\django\shortcuts.py", line 25, in render
    content = loader.render_to_string(template_name, context, request, using=using)
  File "L:\oneSource_Live\venv\Lib\site-packages\django\template\loader.py", line 62, in render_to_string
    return template.render(context, request)
           ~~~~~~~~~~~~~~~^^^^^^^^^^^^^^^^^^
  File "L:\oneSource_Live\venv\Lib\site-packages\django\template\backends\django.py", line 61, in render
    return self.template.render(context)
           ~~~~~~~~~~~~~~~~~~~~^^^^^^^^^
  File "L:\oneSource_Live\venv\Lib\site-packages\django\template\base.py", line 171, in render
    return self._render(context)
           ~~~~~~~~~~~~^^^^^^^^^
  File "L:\oneSource_Live\venv\Lib\site-packages\django\template\base.py", line 163, in _render
    return self.nodelist.render(context)
           ~~~~~~~~~~~~~~~~~~~~^^^^^^^^^
  File "L:\oneSource_Live\venv\Lib\site-packages\django\template\base.py", line 1000, in render
    return SafeString("".join([node.render_annotated(context) for node in self]))
                               ~~~~~~~~~~~~~~~~~~~~~^^^^^^^^^
  File "L:\oneSource_Live\venv\Lib\site-packages\django\template\base.py", line 961, in render_annotated
    return self.render(context)
           ~~~~~~~~~~~^^^^^^^^^
  File "L:\oneSource_Live\venv\Lib\site-packages\django\template\loader_tags.py", line 159, in render
    return compiled_parent._render(context)
           ~~~~~~~~~~~~~~~~~~~~~~~^^^^^^^^^
  File "L:\oneSource_Live\venv\Lib\site-packages\django\template\base.py", line 163, in _render
    return self.nodelist.render(context)
           ~~~~~~~~~~~~~~~~~~~~^^^^^^^^^
  File "L:\oneSource_Live\venv\Lib\site-packages\django\template\base.py", line 1000, in render
    return SafeString("".join([node.render_annotated(context) for node in self]))
                               ~~~~~~~~~~~~~~~~~~~~~^^^^^^^^^
  File "L:\oneSource_Live\venv\Lib\site-packages\django\template\base.py", line 961, in render_annotated
    return self.render(context)
           ~~~~~~~~~~~^^^^^^^^^
  File "L:\oneSource_Live\venv\Lib\site-packages\django\template\loader_tags.py", line 65, in render
    result = block.nodelist.render(context)
  File "L:\oneSource_Live\venv\Lib\site-packages\django\template\base.py", line 1000, in render
    return SafeString("".join([node.render_annotated(context) for node in self]))
                               ~~~~~~~~~~~~~~~~~~~~~^^^^^^^^^
  File "L:\oneSource_Live\venv\Lib\site-packages\django\template\base.py", line 961, in render_annotated
    return self.render(context)
           ~~~~~~~~~~~^^^^^^^^^
  File "L:\oneSource_Live\venv\Lib\site-packages\django\template\defaulttags.py", line 479, in render
    url = reverse(view_name, args=args, kwargs=kwargs, current_app=current_app)
  File "L:\oneSource_Live\venv\Lib\site-packages\django\urls\base.py", line 88, in reverse
    return resolver._reverse_with_prefix(view, prefix, *args, **kwargs)
           ~~~~~~~~~~~~~~~~~~~~~~~~~~~~~^^^^^^^^^^^^^^^^^^^^^^^^^^^^^^^
  File "L:\oneSource_Live\venv\Lib\site-packages\django\urls\resolvers.py", line 851, in _reverse_with_prefix
    raise NoReverseMatch(msg)
django.urls.exceptions.NoReverseMatch: Reverse for 'check_in_status_detail' with no arguments not found. 1 pattern(s) tried: ['check\\-in\\-status/(?P<check_in_status>[^/]+)/\\Z']
[2025-05-14 11:03:14,365] ERROR django.server "GET /check-in-status/No/?from_date=2025-05-01&to_date=2025-05-14&branch=Mumbai&department=IT HTTP/1.1" 500 145
[2025-05-14 11:04:09,220] ERROR django.request Internal Server Error: /check-in-status/all/
Traceback (most recent call last):
  File "L:\oneSource_Live\venv\Lib\site-packages\django\core\handlers\exception.py", line 55, in inner
    response = get_response(request)
  File "L:\oneSource_Live\venv\Lib\site-packages\django\core\handlers\base.py", line 197, in _get_response
    response = wrapped_callback(request, *callback_args, **callback_kwargs)
  File "L:\oneSource_Live\venv\Lib\site-packages\django\contrib\auth\decorators.py", line 23, in _wrapper_view
    return view_func(request, *args, **kwargs)
  File "L:\oneSource_Live\oneSource\HR\views.py", line 660, in check_in_status_detail
    return render(request, 'hr/daily_check_in_status_detail.html', {
        'active_link': 'daily_check_in',
    ...<14 lines>...
        'full_name_query': full_name_query,
    })
  File "L:\oneSource_Live\venv\Lib\site-packages\django\shortcuts.py", line 25, in render
    content = loader.render_to_string(template_name, context, request, using=using)
  File "L:\oneSource_Live\venv\Lib\site-packages\django\template\loader.py", line 62, in render_to_string
    return template.render(context, request)
           ~~~~~~~~~~~~~~~^^^^^^^^^^^^^^^^^^
  File "L:\oneSource_Live\venv\Lib\site-packages\django\template\backends\django.py", line 61, in render
    return self.template.render(context)
           ~~~~~~~~~~~~~~~~~~~~^^^^^^^^^
  File "L:\oneSource_Live\venv\Lib\site-packages\django\template\base.py", line 171, in render
    return self._render(context)
           ~~~~~~~~~~~~^^^^^^^^^
  File "L:\oneSource_Live\venv\Lib\site-packages\django\template\base.py", line 163, in _render
    return self.nodelist.render(context)
           ~~~~~~~~~~~~~~~~~~~~^^^^^^^^^
  File "L:\oneSource_Live\venv\Lib\site-packages\django\template\base.py", line 1000, in render
    return SafeString("".join([node.render_annotated(context) for node in self]))
                               ~~~~~~~~~~~~~~~~~~~~~^^^^^^^^^
  File "L:\oneSource_Live\venv\Lib\site-packages\django\template\base.py", line 961, in render_annotated
    return self.render(context)
           ~~~~~~~~~~~^^^^^^^^^
  File "L:\oneSource_Live\venv\Lib\site-packages\django\template\loader_tags.py", line 159, in render
    return compiled_parent._render(context)
           ~~~~~~~~~~~~~~~~~~~~~~~^^^^^^^^^
  File "L:\oneSource_Live\venv\Lib\site-packages\django\template\base.py", line 163, in _render
    return self.nodelist.render(context)
           ~~~~~~~~~~~~~~~~~~~~^^^^^^^^^
  File "L:\oneSource_Live\venv\Lib\site-packages\django\template\base.py", line 1000, in render
    return SafeString("".join([node.render_annotated(context) for node in self]))
                               ~~~~~~~~~~~~~~~~~~~~~^^^^^^^^^
  File "L:\oneSource_Live\venv\Lib\site-packages\django\template\base.py", line 961, in render_annotated
    return self.render(context)
           ~~~~~~~~~~~^^^^^^^^^
  File "L:\oneSource_Live\venv\Lib\site-packages\django\template\loader_tags.py", line 65, in render
    result = block.nodelist.render(context)
  File "L:\oneSource_Live\venv\Lib\site-packages\django\template\base.py", line 1000, in render
    return SafeString("".join([node.render_annotated(context) for node in self]))
                               ~~~~~~~~~~~~~~~~~~~~~^^^^^^^^^
  File "L:\oneSource_Live\venv\Lib\site-packages\django\template\base.py", line 961, in render_annotated
    return self.render(context)
           ~~~~~~~~~~~^^^^^^^^^
  File "L:\oneSource_Live\venv\Lib\site-packages\django\template\defaulttags.py", line 479, in render
    url = reverse(view_name, args=args, kwargs=kwargs, current_app=current_app)
  File "L:\oneSource_Live\venv\Lib\site-packages\django\urls\base.py", line 88, in reverse
    return resolver._reverse_with_prefix(view, prefix, *args, **kwargs)
           ~~~~~~~~~~~~~~~~~~~~~~~~~~~~~^^^^^^^^^^^^^^^^^^^^^^^^^^^^^^^
  File "L:\oneSource_Live\venv\Lib\site-packages\django\urls\resolvers.py", line 851, in _reverse_with_prefix
    raise NoReverseMatch(msg)
django.urls.exceptions.NoReverseMatch: Reverse for 'check_in_status_detail' with no arguments not found. 1 pattern(s) tried: ['check\\-in\\-status/(?P<check_in_status>[^/]+)/\\Z']
[2025-05-14 11:04:09,230] ERROR django.server "GET /check-in-status/all/?from_date=2025-05-01&to_date=2025-05-14&branch=Mumbai&department=IT HTTP/1.1" 500 145
[2025-05-14 11:04:12,742] ERROR django.request Internal Server Error: /check-in-status/No/
Traceback (most recent call last):
  File "L:\oneSource_Live\venv\Lib\site-packages\django\core\handlers\exception.py", line 55, in inner
    response = get_response(request)
  File "L:\oneSource_Live\venv\Lib\site-packages\django\core\handlers\base.py", line 197, in _get_response
    response = wrapped_callback(request, *callback_args, **callback_kwargs)
  File "L:\oneSource_Live\venv\Lib\site-packages\django\contrib\auth\decorators.py", line 23, in _wrapper_view
    return view_func(request, *args, **kwargs)
  File "L:\oneSource_Live\oneSource\HR\views.py", line 660, in check_in_status_detail
    return render(request, 'hr/daily_check_in_status_detail.html', {
        'active_link': 'daily_check_in',
    ...<14 lines>...
        'full_name_query': full_name_query,
    })
  File "L:\oneSource_Live\venv\Lib\site-packages\django\shortcuts.py", line 25, in render
    content = loader.render_to_string(template_name, context, request, using=using)
  File "L:\oneSource_Live\venv\Lib\site-packages\django\template\loader.py", line 62, in render_to_string
    return template.render(context, request)
           ~~~~~~~~~~~~~~~^^^^^^^^^^^^^^^^^^
  File "L:\oneSource_Live\venv\Lib\site-packages\django\template\backends\django.py", line 61, in render
    return self.template.render(context)
           ~~~~~~~~~~~~~~~~~~~~^^^^^^^^^
  File "L:\oneSource_Live\venv\Lib\site-packages\django\template\base.py", line 171, in render
    return self._render(context)
           ~~~~~~~~~~~~^^^^^^^^^
  File "L:\oneSource_Live\venv\Lib\site-packages\django\template\base.py", line 163, in _render
    return self.nodelist.render(context)
           ~~~~~~~~~~~~~~~~~~~~^^^^^^^^^
  File "L:\oneSource_Live\venv\Lib\site-packages\django\template\base.py", line 1000, in render
    return SafeString("".join([node.render_annotated(context) for node in self]))
                               ~~~~~~~~~~~~~~~~~~~~~^^^^^^^^^
  File "L:\oneSource_Live\venv\Lib\site-packages\django\template\base.py", line 961, in render_annotated
    return self.render(context)
           ~~~~~~~~~~~^^^^^^^^^
  File "L:\oneSource_Live\venv\Lib\site-packages\django\template\loader_tags.py", line 159, in render
    return compiled_parent._render(context)
           ~~~~~~~~~~~~~~~~~~~~~~~^^^^^^^^^
  File "L:\oneSource_Live\venv\Lib\site-packages\django\template\base.py", line 163, in _render
    return self.nodelist.render(context)
           ~~~~~~~~~~~~~~~~~~~~^^^^^^^^^
  File "L:\oneSource_Live\venv\Lib\site-packages\django\template\base.py", line 1000, in render
    return SafeString("".join([node.render_annotated(context) for node in self]))
                               ~~~~~~~~~~~~~~~~~~~~~^^^^^^^^^
  File "L:\oneSource_Live\venv\Lib\site-packages\django\template\base.py", line 961, in render_annotated
    return self.render(context)
           ~~~~~~~~~~~^^^^^^^^^
  File "L:\oneSource_Live\venv\Lib\site-packages\django\template\loader_tags.py", line 65, in render
    result = block.nodelist.render(context)
  File "L:\oneSource_Live\venv\Lib\site-packages\django\template\base.py", line 1000, in render
    return SafeString("".join([node.render_annotated(context) for node in self]))
                               ~~~~~~~~~~~~~~~~~~~~~^^^^^^^^^
  File "L:\oneSource_Live\venv\Lib\site-packages\django\template\base.py", line 961, in render_annotated
    return self.render(context)
           ~~~~~~~~~~~^^^^^^^^^
  File "L:\oneSource_Live\venv\Lib\site-packages\django\template\defaulttags.py", line 479, in render
    url = reverse(view_name, args=args, kwargs=kwargs, current_app=current_app)
  File "L:\oneSource_Live\venv\Lib\site-packages\django\urls\base.py", line 88, in reverse
    return resolver._reverse_with_prefix(view, prefix, *args, **kwargs)
           ~~~~~~~~~~~~~~~~~~~~~~~~~~~~~^^^^^^^^^^^^^^^^^^^^^^^^^^^^^^^
  File "L:\oneSource_Live\venv\Lib\site-packages\django\urls\resolvers.py", line 851, in _reverse_with_prefix
    raise NoReverseMatch(msg)
django.urls.exceptions.NoReverseMatch: Reverse for 'check_in_status_detail' with no arguments not found. 1 pattern(s) tried: ['check\\-in\\-status/(?P<check_in_status>[^/]+)/\\Z']
[2025-05-14 11:04:12,754] ERROR django.server "GET /check-in-status/No/?from_date=2025-05-01&to_date=2025-05-14&branch=Mumbai&department=IT HTTP/1.1" 500 145
[2025-05-14 11:05:57,513] ERROR django.request Internal Server Error: /check-in-status/No/
Traceback (most recent call last):
  File "L:\oneSource_Live\venv\Lib\site-packages\django\core\handlers\exception.py", line 55, in inner
    response = get_response(request)
  File "L:\oneSource_Live\venv\Lib\site-packages\django\core\handlers\base.py", line 197, in _get_response
    response = wrapped_callback(request, *callback_args, **callback_kwargs)
  File "L:\oneSource_Live\venv\Lib\site-packages\django\contrib\auth\decorators.py", line 23, in _wrapper_view
    return view_func(request, *args, **kwargs)
  File "L:\oneSource_Live\oneSource\HR\views.py", line 660, in check_in_status_detail
    return render(request, 'hr/daily_check_in_status_detail.html', {
        'active_link': 'daily_check_in',
    ...<14 lines>...
        'full_name_query': full_name_query,
    })
  File "L:\oneSource_Live\venv\Lib\site-packages\django\shortcuts.py", line 25, in render
    content = loader.render_to_string(template_name, context, request, using=using)
  File "L:\oneSource_Live\venv\Lib\site-packages\django\template\loader.py", line 62, in render_to_string
    return template.render(context, request)
           ~~~~~~~~~~~~~~~^^^^^^^^^^^^^^^^^^
  File "L:\oneSource_Live\venv\Lib\site-packages\django\template\backends\django.py", line 61, in render
    return self.template.render(context)
           ~~~~~~~~~~~~~~~~~~~~^^^^^^^^^
  File "L:\oneSource_Live\venv\Lib\site-packages\django\template\base.py", line 171, in render
    return self._render(context)
           ~~~~~~~~~~~~^^^^^^^^^
  File "L:\oneSource_Live\venv\Lib\site-packages\django\template\base.py", line 163, in _render
    return self.nodelist.render(context)
           ~~~~~~~~~~~~~~~~~~~~^^^^^^^^^
  File "L:\oneSource_Live\venv\Lib\site-packages\django\template\base.py", line 1000, in render
    return SafeString("".join([node.render_annotated(context) for node in self]))
                               ~~~~~~~~~~~~~~~~~~~~~^^^^^^^^^
  File "L:\oneSource_Live\venv\Lib\site-packages\django\template\base.py", line 961, in render_annotated
    return self.render(context)
           ~~~~~~~~~~~^^^^^^^^^
  File "L:\oneSource_Live\venv\Lib\site-packages\django\template\loader_tags.py", line 159, in render
    return compiled_parent._render(context)
           ~~~~~~~~~~~~~~~~~~~~~~~^^^^^^^^^
  File "L:\oneSource_Live\venv\Lib\site-packages\django\template\base.py", line 163, in _render
    return self.nodelist.render(context)
           ~~~~~~~~~~~~~~~~~~~~^^^^^^^^^
  File "L:\oneSource_Live\venv\Lib\site-packages\django\template\base.py", line 1000, in render
    return SafeString("".join([node.render_annotated(context) for node in self]))
                               ~~~~~~~~~~~~~~~~~~~~~^^^^^^^^^
  File "L:\oneSource_Live\venv\Lib\site-packages\django\template\base.py", line 961, in render_annotated
    return self.render(context)
           ~~~~~~~~~~~^^^^^^^^^
  File "L:\oneSource_Live\venv\Lib\site-packages\django\template\loader_tags.py", line 65, in render
    result = block.nodelist.render(context)
  File "L:\oneSource_Live\venv\Lib\site-packages\django\template\base.py", line 1000, in render
    return SafeString("".join([node.render_annotated(context) for node in self]))
                               ~~~~~~~~~~~~~~~~~~~~~^^^^^^^^^
  File "L:\oneSource_Live\venv\Lib\site-packages\django\template\base.py", line 961, in render_annotated
    return self.render(context)
           ~~~~~~~~~~~^^^^^^^^^
  File "L:\oneSource_Live\venv\Lib\site-packages\django\template\defaulttags.py", line 479, in render
    url = reverse(view_name, args=args, kwargs=kwargs, current_app=current_app)
  File "L:\oneSource_Live\venv\Lib\site-packages\django\urls\base.py", line 88, in reverse
    return resolver._reverse_with_prefix(view, prefix, *args, **kwargs)
           ~~~~~~~~~~~~~~~~~~~~~~~~~~~~~^^^^^^^^^^^^^^^^^^^^^^^^^^^^^^^
  File "L:\oneSource_Live\venv\Lib\site-packages\django\urls\resolvers.py", line 851, in _reverse_with_prefix
    raise NoReverseMatch(msg)
django.urls.exceptions.NoReverseMatch: Reverse for 'check_in_status_detail' with no arguments not found. 1 pattern(s) tried: ['check\\-in\\-status/(?P<check_in_status>[^/]+)/\\Z']
[2025-05-14 11:05:57,525] ERROR django.server "GET /check-in-status/No/?from_date=2025-05-01&to_date=2025-05-14&branch=Mumbai&department=IT HTTP/1.1" 500 145
[2025-05-14 11:05:59,182] ERROR django.request Internal Server Error: /check-in-status/No/
Traceback (most recent call last):
  File "L:\oneSource_Live\venv\Lib\site-packages\django\core\handlers\exception.py", line 55, in inner
    response = get_response(request)
  File "L:\oneSource_Live\venv\Lib\site-packages\django\core\handlers\base.py", line 197, in _get_response
    response = wrapped_callback(request, *callback_args, **callback_kwargs)
  File "L:\oneSource_Live\venv\Lib\site-packages\django\contrib\auth\decorators.py", line 23, in _wrapper_view
    return view_func(request, *args, **kwargs)
  File "L:\oneSource_Live\oneSource\HR\views.py", line 660, in check_in_status_detail
    return render(request, 'hr/daily_check_in_status_detail.html', {
        'active_link': 'daily_check_in',
    ...<14 lines>...
        'full_name_query': full_name_query,
    })
  File "L:\oneSource_Live\venv\Lib\site-packages\django\shortcuts.py", line 25, in render
    content = loader.render_to_string(template_name, context, request, using=using)
  File "L:\oneSource_Live\venv\Lib\site-packages\django\template\loader.py", line 62, in render_to_string
    return template.render(context, request)
           ~~~~~~~~~~~~~~~^^^^^^^^^^^^^^^^^^
  File "L:\oneSource_Live\venv\Lib\site-packages\django\template\backends\django.py", line 61, in render
    return self.template.render(context)
           ~~~~~~~~~~~~~~~~~~~~^^^^^^^^^
  File "L:\oneSource_Live\venv\Lib\site-packages\django\template\base.py", line 171, in render
    return self._render(context)
           ~~~~~~~~~~~~^^^^^^^^^
  File "L:\oneSource_Live\venv\Lib\site-packages\django\template\base.py", line 163, in _render
    return self.nodelist.render(context)
           ~~~~~~~~~~~~~~~~~~~~^^^^^^^^^
  File "L:\oneSource_Live\venv\Lib\site-packages\django\template\base.py", line 1000, in render
    return SafeString("".join([node.render_annotated(context) for node in self]))
                               ~~~~~~~~~~~~~~~~~~~~~^^^^^^^^^
  File "L:\oneSource_Live\venv\Lib\site-packages\django\template\base.py", line 961, in render_annotated
    return self.render(context)
           ~~~~~~~~~~~^^^^^^^^^
  File "L:\oneSource_Live\venv\Lib\site-packages\django\template\loader_tags.py", line 159, in render
    return compiled_parent._render(context)
           ~~~~~~~~~~~~~~~~~~~~~~~^^^^^^^^^
  File "L:\oneSource_Live\venv\Lib\site-packages\django\template\base.py", line 163, in _render
    return self.nodelist.render(context)
           ~~~~~~~~~~~~~~~~~~~~^^^^^^^^^
  File "L:\oneSource_Live\venv\Lib\site-packages\django\template\base.py", line 1000, in render
    return SafeString("".join([node.render_annotated(context) for node in self]))
                               ~~~~~~~~~~~~~~~~~~~~~^^^^^^^^^
  File "L:\oneSource_Live\venv\Lib\site-packages\django\template\base.py", line 961, in render_annotated
    return self.render(context)
           ~~~~~~~~~~~^^^^^^^^^
  File "L:\oneSource_Live\venv\Lib\site-packages\django\template\loader_tags.py", line 65, in render
    result = block.nodelist.render(context)
  File "L:\oneSource_Live\venv\Lib\site-packages\django\template\base.py", line 1000, in render
    return SafeString("".join([node.render_annotated(context) for node in self]))
                               ~~~~~~~~~~~~~~~~~~~~~^^^^^^^^^
  File "L:\oneSource_Live\venv\Lib\site-packages\django\template\base.py", line 961, in render_annotated
    return self.render(context)
           ~~~~~~~~~~~^^^^^^^^^
  File "L:\oneSource_Live\venv\Lib\site-packages\django\template\defaulttags.py", line 479, in render
    url = reverse(view_name, args=args, kwargs=kwargs, current_app=current_app)
  File "L:\oneSource_Live\venv\Lib\site-packages\django\urls\base.py", line 88, in reverse
    return resolver._reverse_with_prefix(view, prefix, *args, **kwargs)
           ~~~~~~~~~~~~~~~~~~~~~~~~~~~~~^^^^^^^^^^^^^^^^^^^^^^^^^^^^^^^
  File "L:\oneSource_Live\venv\Lib\site-packages\django\urls\resolvers.py", line 851, in _reverse_with_prefix
    raise NoReverseMatch(msg)
django.urls.exceptions.NoReverseMatch: Reverse for 'check_in_status_detail' with no arguments not found. 1 pattern(s) tried: ['check\\-in\\-status/(?P<check_in_status>[^/]+)/\\Z']
[2025-05-14 11:05:59,200] ERROR django.server "GET /check-in-status/No/?from_date=2025-05-01&to_date=2025-05-14&branch=Mumbai&department=IT HTTP/1.1" 500 145
[2025-05-14 11:06:03,427] ERROR django.request Internal Server Error: /check-in-status/No/
Traceback (most recent call last):
  File "L:\oneSource_Live\venv\Lib\site-packages\django\core\handlers\exception.py", line 55, in inner
    response = get_response(request)
  File "L:\oneSource_Live\venv\Lib\site-packages\django\core\handlers\base.py", line 197, in _get_response
    response = wrapped_callback(request, *callback_args, **callback_kwargs)
  File "L:\oneSource_Live\venv\Lib\site-packages\django\contrib\auth\decorators.py", line 23, in _wrapper_view
    return view_func(request, *args, **kwargs)
  File "L:\oneSource_Live\oneSource\HR\views.py", line 660, in check_in_status_detail
    return render(request, 'hr/daily_check_in_status_detail.html', {
        'active_link': 'daily_check_in',
    ...<14 lines>...
        'full_name_query': full_name_query,
    })
  File "L:\oneSource_Live\venv\Lib\site-packages\django\shortcuts.py", line 25, in render
    content = loader.render_to_string(template_name, context, request, using=using)
  File "L:\oneSource_Live\venv\Lib\site-packages\django\template\loader.py", line 62, in render_to_string
    return template.render(context, request)
           ~~~~~~~~~~~~~~~^^^^^^^^^^^^^^^^^^
  File "L:\oneSource_Live\venv\Lib\site-packages\django\template\backends\django.py", line 61, in render
    return self.template.render(context)
           ~~~~~~~~~~~~~~~~~~~~^^^^^^^^^
  File "L:\oneSource_Live\venv\Lib\site-packages\django\template\base.py", line 171, in render
    return self._render(context)
           ~~~~~~~~~~~~^^^^^^^^^
  File "L:\oneSource_Live\venv\Lib\site-packages\django\template\base.py", line 163, in _render
    return self.nodelist.render(context)
           ~~~~~~~~~~~~~~~~~~~~^^^^^^^^^
  File "L:\oneSource_Live\venv\Lib\site-packages\django\template\base.py", line 1000, in render
    return SafeString("".join([node.render_annotated(context) for node in self]))
                               ~~~~~~~~~~~~~~~~~~~~~^^^^^^^^^
  File "L:\oneSource_Live\venv\Lib\site-packages\django\template\base.py", line 961, in render_annotated
    return self.render(context)
           ~~~~~~~~~~~^^^^^^^^^
  File "L:\oneSource_Live\venv\Lib\site-packages\django\template\loader_tags.py", line 159, in render
    return compiled_parent._render(context)
           ~~~~~~~~~~~~~~~~~~~~~~~^^^^^^^^^
  File "L:\oneSource_Live\venv\Lib\site-packages\django\template\base.py", line 163, in _render
    return self.nodelist.render(context)
           ~~~~~~~~~~~~~~~~~~~~^^^^^^^^^
  File "L:\oneSource_Live\venv\Lib\site-packages\django\template\base.py", line 1000, in render
    return SafeString("".join([node.render_annotated(context) for node in self]))
                               ~~~~~~~~~~~~~~~~~~~~~^^^^^^^^^
  File "L:\oneSource_Live\venv\Lib\site-packages\django\template\base.py", line 961, in render_annotated
    return self.render(context)
           ~~~~~~~~~~~^^^^^^^^^
  File "L:\oneSource_Live\venv\Lib\site-packages\django\template\loader_tags.py", line 65, in render
    result = block.nodelist.render(context)
  File "L:\oneSource_Live\venv\Lib\site-packages\django\template\base.py", line 1000, in render
    return SafeString("".join([node.render_annotated(context) for node in self]))
                               ~~~~~~~~~~~~~~~~~~~~~^^^^^^^^^
  File "L:\oneSource_Live\venv\Lib\site-packages\django\template\base.py", line 961, in render_annotated
    return self.render(context)
           ~~~~~~~~~~~^^^^^^^^^
  File "L:\oneSource_Live\venv\Lib\site-packages\django\template\defaulttags.py", line 479, in render
    url = reverse(view_name, args=args, kwargs=kwargs, current_app=current_app)
  File "L:\oneSource_Live\venv\Lib\site-packages\django\urls\base.py", line 88, in reverse
    return resolver._reverse_with_prefix(view, prefix, *args, **kwargs)
           ~~~~~~~~~~~~~~~~~~~~~~~~~~~~~^^^^^^^^^^^^^^^^^^^^^^^^^^^^^^^
  File "L:\oneSource_Live\venv\Lib\site-packages\django\urls\resolvers.py", line 851, in _reverse_with_prefix
    raise NoReverseMatch(msg)
django.urls.exceptions.NoReverseMatch: Reverse for 'check_in_status_detail' with no arguments not found. 1 pattern(s) tried: ['check\\-in\\-status/(?P<check_in_status>[^/]+)/\\Z']
[2025-05-14 11:06:03,435] ERROR django.server "GET /check-in-status/No/?from_date=2025-05-01&to_date=2025-05-14&branch=Mumbai&department=IT HTTP/1.1" 500 145
[2025-05-14 12:31:58,504] ERROR django.request Internal Server Error: /search_equipment/
Traceback (most recent call last):
  File "L:\oneSource_Live\venv\Lib\site-packages\django\db\backends\base\base.py", line 275, in ensure_connection
    self.connect()
    ~~~~~~~~~~~~^^
  File "L:\oneSource_Live\venv\Lib\site-packages\django\utils\asyncio.py", line 26, in inner
    return func(*args, **kwargs)
  File "L:\oneSource_Live\venv\Lib\site-packages\django\db\backends\base\base.py", line 256, in connect
    self.connection = self.get_new_connection(conn_params)
                      ~~~~~~~~~~~~~~~~~~~~~~~^^^^^^^^^^^^^
  File "L:\oneSource_Live\venv\Lib\site-packages\mssql\base.py", line 368, in get_new_connection
    conn = Database.connect(connstr, **args)
pyodbc.OperationalError: ('08S01', '[08S01] [Microsoft][ODBC Driver 17 for SQL Server]Communication link failure (0) (SQLSetConnectAttr(SQL_ATTR_AUTOCOMMIT)); [08S01] [Microsoft][ODBC Driver 17 for SQL Server]The connection is broken and recovery is not possible. The client driver attempted to recover the connection one or more times and all attempts failed. Increase the value of ConnectRetryCount to increase the number of recovery attempts. (0)')

The above exception was the direct cause of the following exception:

Traceback (most recent call last):
  File "L:\oneSource_Live\venv\Lib\site-packages\django\core\handlers\exception.py", line 55, in inner
    response = get_response(request)
  File "L:\oneSource_Live\venv\Lib\site-packages\django\core\handlers\base.py", line 197, in _get_response
    response = wrapped_callback(request, *callback_args, **callback_kwargs)
  File "L:\oneSource_Live\venv\Lib\site-packages\django\views\decorators\csrf.py", line 65, in _view_wrapper
    return view_func(request, *args, **kwargs)
  File "L:\oneSource_Live\oneSource\PRODUCTION\views.py", line 87, in search_equipment
    with connections['readonly_db'].cursor() as cursor:
         ~~~~~~~~~~~~~~~~~~~~~~~~~~~~~~~~~^^
  File "L:\oneSource_Live\venv\Lib\site-packages\django\utils\asyncio.py", line 26, in inner
    return func(*args, **kwargs)
  File "L:\oneSource_Live\venv\Lib\site-packages\django\db\backends\base\base.py", line 316, in cursor
    return self._cursor()
           ~~~~~~~~~~~~^^
  File "L:\oneSource_Live\venv\Lib\site-packages\mssql\base.py", line 261, in _cursor
    conn = super()._cursor()
  File "L:\oneSource_Live\venv\Lib\site-packages\django\db\backends\base\base.py", line 292, in _cursor
    self.ensure_connection()
    ~~~~~~~~~~~~~~~~~~~~~~^^
  File "L:\oneSource_Live\venv\Lib\site-packages\django\utils\asyncio.py", line 26, in inner
    return func(*args, **kwargs)
  File "L:\oneSource_Live\venv\Lib\site-packages\django\db\backends\base\base.py", line 274, in ensure_connection
    with self.wrap_database_errors:
         ^^^^^^^^^^^^^^^^^^^^^^^^^
  File "L:\oneSource_Live\venv\Lib\site-packages\django\db\utils.py", line 91, in __exit__
    raise dj_exc_value.with_traceback(traceback) from exc_value
  File "L:\oneSource_Live\venv\Lib\site-packages\django\db\backends\base\base.py", line 275, in ensure_connection
    self.connect()
    ~~~~~~~~~~~~^^
  File "L:\oneSource_Live\venv\Lib\site-packages\django\utils\asyncio.py", line 26, in inner
    return func(*args, **kwargs)
  File "L:\oneSource_Live\venv\Lib\site-packages\django\db\backends\base\base.py", line 256, in connect
    self.connection = self.get_new_connection(conn_params)
                      ~~~~~~~~~~~~~~~~~~~~~~~^^^^^^^^^^^^^
  File "L:\oneSource_Live\venv\Lib\site-packages\mssql\base.py", line 368, in get_new_connection
    conn = Database.connect(connstr, **args)
django.db.utils.OperationalError: ('08S01', '[08S01] [Microsoft][ODBC Driver 17 for SQL Server]Communication link failure (0) (SQLSetConnectAttr(SQL_ATTR_AUTOCOMMIT)); [08S01] [Microsoft][ODBC Driver 17 for SQL Server]The connection is broken and recovery is not possible. The client driver attempted to recover the connection one or more times and all attempts failed. Increase the value of ConnectRetryCount to increase the number of recovery attempts. (0)')
[2025-05-14 12:31:58,521] ERROR django.server "GET /search_equipment/ HTTP/1.1" 500 145
[2025-05-14 12:32:00,285] ERROR django.request Internal Server Error: /search_equipment/
Traceback (most recent call last):
  File "L:\oneSource_Live\venv\Lib\site-packages\django\db\backends\base\base.py", line 275, in ensure_connection
    self.connect()
    ~~~~~~~~~~~~^^
  File "L:\oneSource_Live\venv\Lib\site-packages\django\utils\asyncio.py", line 26, in inner
    return func(*args, **kwargs)
  File "L:\oneSource_Live\venv\Lib\site-packages\django\db\backends\base\base.py", line 256, in connect
    self.connection = self.get_new_connection(conn_params)
                      ~~~~~~~~~~~~~~~~~~~~~~~^^^^^^^^^^^^^
  File "L:\oneSource_Live\venv\Lib\site-packages\mssql\base.py", line 368, in get_new_connection
    conn = Database.connect(connstr, **args)
pyodbc.OperationalError: ('08S01', '[08S01] [Microsoft][ODBC Driver 17 for SQL Server]Communication link failure (0) (SQLSetConnectAttr(SQL_ATTR_AUTOCOMMIT)); [08S01] [Microsoft][ODBC Driver 17 for SQL Server]The connection is broken and recovery is not possible. The client driver attempted to recover the connection one or more times and all attempts failed. Increase the value of ConnectRetryCount to increase the number of recovery attempts. (0)')

The above exception was the direct cause of the following exception:

Traceback (most recent call last):
  File "L:\oneSource_Live\venv\Lib\site-packages\django\core\handlers\exception.py", line 55, in inner
    response = get_response(request)
  File "L:\oneSource_Live\venv\Lib\site-packages\django\core\handlers\base.py", line 197, in _get_response
    response = wrapped_callback(request, *callback_args, **callback_kwargs)
  File "L:\oneSource_Live\venv\Lib\site-packages\django\views\decorators\csrf.py", line 65, in _view_wrapper
    return view_func(request, *args, **kwargs)
  File "L:\oneSource_Live\oneSource\PRODUCTION\views.py", line 87, in search_equipment
    with connections['readonly_db'].cursor() as cursor:
         ~~~~~~~~~~~~~~~~~~~~~~~~~~~~~~~~~^^
  File "L:\oneSource_Live\venv\Lib\site-packages\django\utils\asyncio.py", line 26, in inner
    return func(*args, **kwargs)
  File "L:\oneSource_Live\venv\Lib\site-packages\django\db\backends\base\base.py", line 316, in cursor
    return self._cursor()
           ~~~~~~~~~~~~^^
  File "L:\oneSource_Live\venv\Lib\site-packages\mssql\base.py", line 261, in _cursor
    conn = super()._cursor()
  File "L:\oneSource_Live\venv\Lib\site-packages\django\db\backends\base\base.py", line 292, in _cursor
    self.ensure_connection()
    ~~~~~~~~~~~~~~~~~~~~~~^^
  File "L:\oneSource_Live\venv\Lib\site-packages\django\utils\asyncio.py", line 26, in inner
    return func(*args, **kwargs)
  File "L:\oneSource_Live\venv\Lib\site-packages\django\db\backends\base\base.py", line 274, in ensure_connection
    with self.wrap_database_errors:
         ^^^^^^^^^^^^^^^^^^^^^^^^^
  File "L:\oneSource_Live\venv\Lib\site-packages\django\db\utils.py", line 91, in __exit__
    raise dj_exc_value.with_traceback(traceback) from exc_value
  File "L:\oneSource_Live\venv\Lib\site-packages\django\db\backends\base\base.py", line 275, in ensure_connection
    self.connect()
    ~~~~~~~~~~~~^^
  File "L:\oneSource_Live\venv\Lib\site-packages\django\utils\asyncio.py", line 26, in inner
    return func(*args, **kwargs)
  File "L:\oneSource_Live\venv\Lib\site-packages\django\db\backends\base\base.py", line 256, in connect
    self.connection = self.get_new_connection(conn_params)
                      ~~~~~~~~~~~~~~~~~~~~~~~^^^^^^^^^^^^^
  File "L:\oneSource_Live\venv\Lib\site-packages\mssql\base.py", line 368, in get_new_connection
    conn = Database.connect(connstr, **args)
django.db.utils.OperationalError: ('08S01', '[08S01] [Microsoft][ODBC Driver 17 for SQL Server]Communication link failure (0) (SQLSetConnectAttr(SQL_ATTR_AUTOCOMMIT)); [08S01] [Microsoft][ODBC Driver 17 for SQL Server]The connection is broken and recovery is not possible. The client driver attempted to recover the connection one or more times and all attempts failed. Increase the value of ConnectRetryCount to increase the number of recovery attempts. (0)')
[2025-05-14 12:32:00,292] ERROR django.server "GET /search_equipment/?term=c HTTP/1.1" 500 145
[2025-05-14 12:32:00,601] ERROR django.request Internal Server Error: /search_equipment/
Traceback (most recent call last):
  File "L:\oneSource_Live\venv\Lib\site-packages\django\db\backends\base\base.py", line 275, in ensure_connection
    self.connect()
    ~~~~~~~~~~~~^^
  File "L:\oneSource_Live\venv\Lib\site-packages\django\utils\asyncio.py", line 26, in inner
    return func(*args, **kwargs)
  File "L:\oneSource_Live\venv\Lib\site-packages\django\db\backends\base\base.py", line 256, in connect
    self.connection = self.get_new_connection(conn_params)
                      ~~~~~~~~~~~~~~~~~~~~~~~^^^^^^^^^^^^^
  File "L:\oneSource_Live\venv\Lib\site-packages\mssql\base.py", line 368, in get_new_connection
    conn = Database.connect(connstr, **args)
pyodbc.OperationalError: ('08S01', '[08S01] [Microsoft][ODBC Driver 17 for SQL Server]Communication link failure (0) (SQLSetConnectAttr(SQL_ATTR_AUTOCOMMIT)); [08S01] [Microsoft][ODBC Driver 17 for SQL Server]The connection is broken and recovery is not possible. The client driver attempted to recover the connection one or more times and all attempts failed. Increase the value of ConnectRetryCount to increase the number of recovery attempts. (0)')

The above exception was the direct cause of the following exception:

Traceback (most recent call last):
  File "L:\oneSource_Live\venv\Lib\site-packages\django\core\handlers\exception.py", line 55, in inner
    response = get_response(request)
  File "L:\oneSource_Live\venv\Lib\site-packages\django\core\handlers\base.py", line 197, in _get_response
    response = wrapped_callback(request, *callback_args, **callback_kwargs)
  File "L:\oneSource_Live\venv\Lib\site-packages\django\views\decorators\csrf.py", line 65, in _view_wrapper
    return view_func(request, *args, **kwargs)
  File "L:\oneSource_Live\oneSource\PRODUCTION\views.py", line 87, in search_equipment
    with connections['readonly_db'].cursor() as cursor:
         ~~~~~~~~~~~~~~~~~~~~~~~~~~~~~~~~~^^
  File "L:\oneSource_Live\venv\Lib\site-packages\django\utils\asyncio.py", line 26, in inner
    return func(*args, **kwargs)
  File "L:\oneSource_Live\venv\Lib\site-packages\django\db\backends\base\base.py", line 316, in cursor
    return self._cursor()
           ~~~~~~~~~~~~^^
  File "L:\oneSource_Live\venv\Lib\site-packages\mssql\base.py", line 261, in _cursor
    conn = super()._cursor()
  File "L:\oneSource_Live\venv\Lib\site-packages\django\db\backends\base\base.py", line 292, in _cursor
    self.ensure_connection()
    ~~~~~~~~~~~~~~~~~~~~~~^^
  File "L:\oneSource_Live\venv\Lib\site-packages\django\utils\asyncio.py", line 26, in inner
    return func(*args, **kwargs)
  File "L:\oneSource_Live\venv\Lib\site-packages\django\db\backends\base\base.py", line 274, in ensure_connection
    with self.wrap_database_errors:
         ^^^^^^^^^^^^^^^^^^^^^^^^^
  File "L:\oneSource_Live\venv\Lib\site-packages\django\db\utils.py", line 91, in __exit__
    raise dj_exc_value.with_traceback(traceback) from exc_value
  File "L:\oneSource_Live\venv\Lib\site-packages\django\db\backends\base\base.py", line 275, in ensure_connection
    self.connect()
    ~~~~~~~~~~~~^^
  File "L:\oneSource_Live\venv\Lib\site-packages\django\utils\asyncio.py", line 26, in inner
    return func(*args, **kwargs)
  File "L:\oneSource_Live\venv\Lib\site-packages\django\db\backends\base\base.py", line 256, in connect
    self.connection = self.get_new_connection(conn_params)
                      ~~~~~~~~~~~~~~~~~~~~~~~^^^^^^^^^^^^^
  File "L:\oneSource_Live\venv\Lib\site-packages\mssql\base.py", line 368, in get_new_connection
    conn = Database.connect(connstr, **args)
django.db.utils.OperationalError: ('08S01', '[08S01] [Microsoft][ODBC Driver 17 for SQL Server]Communication link failure (0) (SQLSetConnectAttr(SQL_ATTR_AUTOCOMMIT)); [08S01] [Microsoft][ODBC Driver 17 for SQL Server]The connection is broken and recovery is not possible. The client driver attempted to recover the connection one or more times and all attempts failed. Increase the value of ConnectRetryCount to increase the number of recovery attempts. (0)')
[2025-05-14 12:32:00,608] ERROR django.server "GET /search_equipment/?term=cr HTTP/1.1" 500 145
[2025-05-14 12:32:01,108] ERROR django.request Internal Server Error: /search_equipment/
Traceback (most recent call last):
  File "L:\oneSource_Live\venv\Lib\site-packages\django\db\backends\base\base.py", line 275, in ensure_connection
    self.connect()
    ~~~~~~~~~~~~^^
  File "L:\oneSource_Live\venv\Lib\site-packages\django\utils\asyncio.py", line 26, in inner
    return func(*args, **kwargs)
  File "L:\oneSource_Live\venv\Lib\site-packages\django\db\backends\base\base.py", line 256, in connect
    self.connection = self.get_new_connection(conn_params)
                      ~~~~~~~~~~~~~~~~~~~~~~~^^^^^^^^^^^^^
  File "L:\oneSource_Live\venv\Lib\site-packages\mssql\base.py", line 368, in get_new_connection
    conn = Database.connect(connstr, **args)
pyodbc.OperationalError: ('08S01', '[08S01] [Microsoft][ODBC Driver 17 for SQL Server]Communication link failure (0) (SQLSetConnectAttr(SQL_ATTR_AUTOCOMMIT)); [08S01] [Microsoft][ODBC Driver 17 for SQL Server]The connection is broken and recovery is not possible. The client driver attempted to recover the connection one or more times and all attempts failed. Increase the value of ConnectRetryCount to increase the number of recovery attempts. (0)')

The above exception was the direct cause of the following exception:

Traceback (most recent call last):
  File "L:\oneSource_Live\venv\Lib\site-packages\django\core\handlers\exception.py", line 55, in inner
    response = get_response(request)
  File "L:\oneSource_Live\venv\Lib\site-packages\django\core\handlers\base.py", line 197, in _get_response
    response = wrapped_callback(request, *callback_args, **callback_kwargs)
  File "L:\oneSource_Live\venv\Lib\site-packages\django\views\decorators\csrf.py", line 65, in _view_wrapper
    return view_func(request, *args, **kwargs)
  File "L:\oneSource_Live\oneSource\PRODUCTION\views.py", line 87, in search_equipment
    with connections['readonly_db'].cursor() as cursor:
         ~~~~~~~~~~~~~~~~~~~~~~~~~~~~~~~~~^^
  File "L:\oneSource_Live\venv\Lib\site-packages\django\utils\asyncio.py", line 26, in inner
    return func(*args, **kwargs)
  File "L:\oneSource_Live\venv\Lib\site-packages\django\db\backends\base\base.py", line 316, in cursor
    return self._cursor()
           ~~~~~~~~~~~~^^
  File "L:\oneSource_Live\venv\Lib\site-packages\mssql\base.py", line 261, in _cursor
    conn = super()._cursor()
  File "L:\oneSource_Live\venv\Lib\site-packages\django\db\backends\base\base.py", line 292, in _cursor
    self.ensure_connection()
    ~~~~~~~~~~~~~~~~~~~~~~^^
  File "L:\oneSource_Live\venv\Lib\site-packages\django\utils\asyncio.py", line 26, in inner
    return func(*args, **kwargs)
  File "L:\oneSource_Live\venv\Lib\site-packages\django\db\backends\base\base.py", line 274, in ensure_connection
    with self.wrap_database_errors:
         ^^^^^^^^^^^^^^^^^^^^^^^^^
  File "L:\oneSource_Live\venv\Lib\site-packages\django\db\utils.py", line 91, in __exit__
    raise dj_exc_value.with_traceback(traceback) from exc_value
  File "L:\oneSource_Live\venv\Lib\site-packages\django\db\backends\base\base.py", line 275, in ensure_connection
    self.connect()
    ~~~~~~~~~~~~^^
  File "L:\oneSource_Live\venv\Lib\site-packages\django\utils\asyncio.py", line 26, in inner
    return func(*args, **kwargs)
  File "L:\oneSource_Live\venv\Lib\site-packages\django\db\backends\base\base.py", line 256, in connect
    self.connection = self.get_new_connection(conn_params)
                      ~~~~~~~~~~~~~~~~~~~~~~~^^^^^^^^^^^^^
  File "L:\oneSource_Live\venv\Lib\site-packages\mssql\base.py", line 368, in get_new_connection
    conn = Database.connect(connstr, **args)
django.db.utils.OperationalError: ('08S01', '[08S01] [Microsoft][ODBC Driver 17 for SQL Server]Communication link failure (0) (SQLSetConnectAttr(SQL_ATTR_AUTOCOMMIT)); [08S01] [Microsoft][ODBC Driver 17 for SQL Server]The connection is broken and recovery is not possible. The client driver attempted to recover the connection one or more times and all attempts failed. Increase the value of ConnectRetryCount to increase the number of recovery attempts. (0)')
[2025-05-14 12:32:01,112] ERROR django.server "GET /search_equipment/?term=cr- HTTP/1.1" 500 145
[2025-05-14 12:32:01,954] ERROR django.request Internal Server Error: /search_equipment/
Traceback (most recent call last):
  File "L:\oneSource_Live\venv\Lib\site-packages\django\db\backends\base\base.py", line 275, in ensure_connection
    self.connect()
    ~~~~~~~~~~~~^^
  File "L:\oneSource_Live\venv\Lib\site-packages\django\utils\asyncio.py", line 26, in inner
    return func(*args, **kwargs)
  File "L:\oneSource_Live\venv\Lib\site-packages\django\db\backends\base\base.py", line 256, in connect
    self.connection = self.get_new_connection(conn_params)
                      ~~~~~~~~~~~~~~~~~~~~~~~^^^^^^^^^^^^^
  File "L:\oneSource_Live\venv\Lib\site-packages\mssql\base.py", line 368, in get_new_connection
    conn = Database.connect(connstr, **args)
pyodbc.OperationalError: ('08S01', '[08S01] [Microsoft][ODBC Driver 17 for SQL Server]Communication link failure (0) (SQLSetConnectAttr(SQL_ATTR_AUTOCOMMIT)); [08S01] [Microsoft][ODBC Driver 17 for SQL Server]The connection is broken and recovery is not possible. The client driver attempted to recover the connection one or more times and all attempts failed. Increase the value of ConnectRetryCount to increase the number of recovery attempts. (0)')

The above exception was the direct cause of the following exception:

Traceback (most recent call last):
  File "L:\oneSource_Live\venv\Lib\site-packages\django\core\handlers\exception.py", line 55, in inner
    response = get_response(request)
  File "L:\oneSource_Live\venv\Lib\site-packages\django\core\handlers\base.py", line 197, in _get_response
    response = wrapped_callback(request, *callback_args, **callback_kwargs)
  File "L:\oneSource_Live\venv\Lib\site-packages\django\views\decorators\csrf.py", line 65, in _view_wrapper
    return view_func(request, *args, **kwargs)
  File "L:\oneSource_Live\oneSource\PRODUCTION\views.py", line 87, in search_equipment
    with connections['readonly_db'].cursor() as cursor:
         ~~~~~~~~~~~~~~~~~~~~~~~~~~~~~~~~~^^
  File "L:\oneSource_Live\venv\Lib\site-packages\django\utils\asyncio.py", line 26, in inner
    return func(*args, **kwargs)
  File "L:\oneSource_Live\venv\Lib\site-packages\django\db\backends\base\base.py", line 316, in cursor
    return self._cursor()
           ~~~~~~~~~~~~^^
  File "L:\oneSource_Live\venv\Lib\site-packages\mssql\base.py", line 261, in _cursor
    conn = super()._cursor()
  File "L:\oneSource_Live\venv\Lib\site-packages\django\db\backends\base\base.py", line 292, in _cursor
    self.ensure_connection()
    ~~~~~~~~~~~~~~~~~~~~~~^^
  File "L:\oneSource_Live\venv\Lib\site-packages\django\utils\asyncio.py", line 26, in inner
    return func(*args, **kwargs)
  File "L:\oneSource_Live\venv\Lib\site-packages\django\db\backends\base\base.py", line 274, in ensure_connection
    with self.wrap_database_errors:
         ^^^^^^^^^^^^^^^^^^^^^^^^^
  File "L:\oneSource_Live\venv\Lib\site-packages\django\db\utils.py", line 91, in __exit__
    raise dj_exc_value.with_traceback(traceback) from exc_value
  File "L:\oneSource_Live\venv\Lib\site-packages\django\db\backends\base\base.py", line 275, in ensure_connection
    self.connect()
    ~~~~~~~~~~~~^^
  File "L:\oneSource_Live\venv\Lib\site-packages\django\utils\asyncio.py", line 26, in inner
    return func(*args, **kwargs)
  File "L:\oneSource_Live\venv\Lib\site-packages\django\db\backends\base\base.py", line 256, in connect
    self.connection = self.get_new_connection(conn_params)
                      ~~~~~~~~~~~~~~~~~~~~~~~^^^^^^^^^^^^^
  File "L:\oneSource_Live\venv\Lib\site-packages\mssql\base.py", line 368, in get_new_connection
    conn = Database.connect(connstr, **args)
django.db.utils.OperationalError: ('08S01', '[08S01] [Microsoft][ODBC Driver 17 for SQL Server]Communication link failure (0) (SQLSetConnectAttr(SQL_ATTR_AUTOCOMMIT)); [08S01] [Microsoft][ODBC Driver 17 for SQL Server]The connection is broken and recovery is not possible. The client driver attempted to recover the connection one or more times and all attempts failed. Increase the value of ConnectRetryCount to increase the number of recovery attempts. (0)')
[2025-05-14 12:32:01,957] ERROR django.server "GET /search_equipment/?term=cr-201 HTTP/1.1" 500 145
[2025-05-14 12:32:09,230] ERROR django.request Internal Server Error: /search_equipment/
Traceback (most recent call last):
  File "L:\oneSource_Live\venv\Lib\site-packages\django\db\backends\base\base.py", line 275, in ensure_connection
    self.connect()
    ~~~~~~~~~~~~^^
  File "L:\oneSource_Live\venv\Lib\site-packages\django\utils\asyncio.py", line 26, in inner
    return func(*args, **kwargs)
  File "L:\oneSource_Live\venv\Lib\site-packages\django\db\backends\base\base.py", line 256, in connect
    self.connection = self.get_new_connection(conn_params)
                      ~~~~~~~~~~~~~~~~~~~~~~~^^^^^^^^^^^^^
  File "L:\oneSource_Live\venv\Lib\site-packages\mssql\base.py", line 368, in get_new_connection
    conn = Database.connect(connstr, **args)
pyodbc.OperationalError: ('08S01', '[08S01] [Microsoft][ODBC Driver 17 for SQL Server]Communication link failure (0) (SQLSetConnectAttr(SQL_ATTR_AUTOCOMMIT)); [08S01] [Microsoft][ODBC Driver 17 for SQL Server]The connection is broken and recovery is not possible. The client driver attempted to recover the connection one or more times and all attempts failed. Increase the value of ConnectRetryCount to increase the number of recovery attempts. (0)')

The above exception was the direct cause of the following exception:

Traceback (most recent call last):
  File "L:\oneSource_Live\venv\Lib\site-packages\django\core\handlers\exception.py", line 55, in inner
    response = get_response(request)
  File "L:\oneSource_Live\venv\Lib\site-packages\django\core\handlers\base.py", line 197, in _get_response
    response = wrapped_callback(request, *callback_args, **callback_kwargs)
  File "L:\oneSource_Live\venv\Lib\site-packages\django\views\decorators\csrf.py", line 65, in _view_wrapper
    return view_func(request, *args, **kwargs)
  File "L:\oneSource_Live\oneSource\PRODUCTION\views.py", line 87, in search_equipment
    with connections['readonly_db'].cursor() as cursor:
         ~~~~~~~~~~~~~~~~~~~~~~~~~~~~~~~~~^^
  File "L:\oneSource_Live\venv\Lib\site-packages\django\utils\asyncio.py", line 26, in inner
    return func(*args, **kwargs)
  File "L:\oneSource_Live\venv\Lib\site-packages\django\db\backends\base\base.py", line 316, in cursor
    return self._cursor()
           ~~~~~~~~~~~~^^
  File "L:\oneSource_Live\venv\Lib\site-packages\mssql\base.py", line 261, in _cursor
    conn = super()._cursor()
  File "L:\oneSource_Live\venv\Lib\site-packages\django\db\backends\base\base.py", line 292, in _cursor
    self.ensure_connection()
    ~~~~~~~~~~~~~~~~~~~~~~^^
  File "L:\oneSource_Live\venv\Lib\site-packages\django\utils\asyncio.py", line 26, in inner
    return func(*args, **kwargs)
  File "L:\oneSource_Live\venv\Lib\site-packages\django\db\backends\base\base.py", line 274, in ensure_connection
    with self.wrap_database_errors:
         ^^^^^^^^^^^^^^^^^^^^^^^^^
  File "L:\oneSource_Live\venv\Lib\site-packages\django\db\utils.py", line 91, in __exit__
    raise dj_exc_value.with_traceback(traceback) from exc_value
  File "L:\oneSource_Live\venv\Lib\site-packages\django\db\backends\base\base.py", line 275, in ensure_connection
    self.connect()
    ~~~~~~~~~~~~^^
  File "L:\oneSource_Live\venv\Lib\site-packages\django\utils\asyncio.py", line 26, in inner
    return func(*args, **kwargs)
  File "L:\oneSource_Live\venv\Lib\site-packages\django\db\backends\base\base.py", line 256, in connect
    self.connection = self.get_new_connection(conn_params)
                      ~~~~~~~~~~~~~~~~~~~~~~~^^^^^^^^^^^^^
  File "L:\oneSource_Live\venv\Lib\site-packages\mssql\base.py", line 368, in get_new_connection
    conn = Database.connect(connstr, **args)
django.db.utils.OperationalError: ('08S01', '[08S01] [Microsoft][ODBC Driver 17 for SQL Server]Communication link failure (0) (SQLSetConnectAttr(SQL_ATTR_AUTOCOMMIT)); [08S01] [Microsoft][ODBC Driver 17 for SQL Server]The connection is broken and recovery is not possible. The client driver attempted to recover the connection one or more times and all attempts failed. Increase the value of ConnectRetryCount to increase the number of recovery attempts. (0)')
[2025-05-14 12:32:09,236] ERROR django.server "GET /search_equipment/?term=201 HTTP/1.1" 500 145
[2025-05-14 12:32:11,273] ERROR django.request Internal Server Error: /search_equipment/
Traceback (most recent call last):
  File "L:\oneSource_Live\venv\Lib\site-packages\django\db\backends\base\base.py", line 275, in ensure_connection
    self.connect()
    ~~~~~~~~~~~~^^
  File "L:\oneSource_Live\venv\Lib\site-packages\django\utils\asyncio.py", line 26, in inner
    return func(*args, **kwargs)
  File "L:\oneSource_Live\venv\Lib\site-packages\django\db\backends\base\base.py", line 256, in connect
    self.connection = self.get_new_connection(conn_params)
                      ~~~~~~~~~~~~~~~~~~~~~~~^^^^^^^^^^^^^
  File "L:\oneSource_Live\venv\Lib\site-packages\mssql\base.py", line 368, in get_new_connection
    conn = Database.connect(connstr, **args)
pyodbc.OperationalError: ('08S01', '[08S01] [Microsoft][ODBC Driver 17 for SQL Server]Communication link failure (0) (SQLSetConnectAttr(SQL_ATTR_AUTOCOMMIT)); [08S01] [Microsoft][ODBC Driver 17 for SQL Server]The connection is broken and recovery is not possible. The client driver attempted to recover the connection one or more times and all attempts failed. Increase the value of ConnectRetryCount to increase the number of recovery attempts. (0)')

The above exception was the direct cause of the following exception:

Traceback (most recent call last):
  File "L:\oneSource_Live\venv\Lib\site-packages\django\core\handlers\exception.py", line 55, in inner
    response = get_response(request)
  File "L:\oneSource_Live\venv\Lib\site-packages\django\core\handlers\base.py", line 197, in _get_response
    response = wrapped_callback(request, *callback_args, **callback_kwargs)
  File "L:\oneSource_Live\venv\Lib\site-packages\django\views\decorators\csrf.py", line 65, in _view_wrapper
    return view_func(request, *args, **kwargs)
  File "L:\oneSource_Live\oneSource\PRODUCTION\views.py", line 87, in search_equipment
    with connections['readonly_db'].cursor() as cursor:
         ~~~~~~~~~~~~~~~~~~~~~~~~~~~~~~~~~^^
  File "L:\oneSource_Live\venv\Lib\site-packages\django\utils\asyncio.py", line 26, in inner
    return func(*args, **kwargs)
  File "L:\oneSource_Live\venv\Lib\site-packages\django\db\backends\base\base.py", line 316, in cursor
    return self._cursor()
           ~~~~~~~~~~~~^^
  File "L:\oneSource_Live\venv\Lib\site-packages\mssql\base.py", line 261, in _cursor
    conn = super()._cursor()
  File "L:\oneSource_Live\venv\Lib\site-packages\django\db\backends\base\base.py", line 292, in _cursor
    self.ensure_connection()
    ~~~~~~~~~~~~~~~~~~~~~~^^
  File "L:\oneSource_Live\venv\Lib\site-packages\django\utils\asyncio.py", line 26, in inner
    return func(*args, **kwargs)
  File "L:\oneSource_Live\venv\Lib\site-packages\django\db\backends\base\base.py", line 274, in ensure_connection
    with self.wrap_database_errors:
         ^^^^^^^^^^^^^^^^^^^^^^^^^
  File "L:\oneSource_Live\venv\Lib\site-packages\django\db\utils.py", line 91, in __exit__
    raise dj_exc_value.with_traceback(traceback) from exc_value
  File "L:\oneSource_Live\venv\Lib\site-packages\django\db\backends\base\base.py", line 275, in ensure_connection
    self.connect()
    ~~~~~~~~~~~~^^
  File "L:\oneSource_Live\venv\Lib\site-packages\django\utils\asyncio.py", line 26, in inner
    return func(*args, **kwargs)
  File "L:\oneSource_Live\venv\Lib\site-packages\django\db\backends\base\base.py", line 256, in connect
    self.connection = self.get_new_connection(conn_params)
                      ~~~~~~~~~~~~~~~~~~~~~~~^^^^^^^^^^^^^
  File "L:\oneSource_Live\venv\Lib\site-packages\mssql\base.py", line 368, in get_new_connection
    conn = Database.connect(connstr, **args)
django.db.utils.OperationalError: ('08S01', '[08S01] [Microsoft][ODBC Driver 17 for SQL Server]Communication link failure (0) (SQLSetConnectAttr(SQL_ATTR_AUTOCOMMIT)); [08S01] [Microsoft][ODBC Driver 17 for SQL Server]The connection is broken and recovery is not possible. The client driver attempted to recover the connection one or more times and all attempts failed. Increase the value of ConnectRetryCount to increase the number of recovery attempts. (0)')
[2025-05-14 12:32:11,282] ERROR django.server "GET /search_equipment/ HTTP/1.1" 500 145
[2025-05-14 12:32:13,194] ERROR django.request Internal Server Error: /search_equipment/
Traceback (most recent call last):
  File "L:\oneSource_Live\venv\Lib\site-packages\django\db\backends\base\base.py", line 275, in ensure_connection
    self.connect()
    ~~~~~~~~~~~~^^
  File "L:\oneSource_Live\venv\Lib\site-packages\django\utils\asyncio.py", line 26, in inner
    return func(*args, **kwargs)
  File "L:\oneSource_Live\venv\Lib\site-packages\django\db\backends\base\base.py", line 256, in connect
    self.connection = self.get_new_connection(conn_params)
                      ~~~~~~~~~~~~~~~~~~~~~~~^^^^^^^^^^^^^
  File "L:\oneSource_Live\venv\Lib\site-packages\mssql\base.py", line 368, in get_new_connection
    conn = Database.connect(connstr, **args)
pyodbc.OperationalError: ('08S01', '[08S01] [Microsoft][ODBC Driver 17 for SQL Server]Communication link failure (0) (SQLSetConnectAttr(SQL_ATTR_AUTOCOMMIT)); [08S01] [Microsoft][ODBC Driver 17 for SQL Server]The connection is broken and recovery is not possible. The client driver attempted to recover the connection one or more times and all attempts failed. Increase the value of ConnectRetryCount to increase the number of recovery attempts. (0)')

The above exception was the direct cause of the following exception:

Traceback (most recent call last):
  File "L:\oneSource_Live\venv\Lib\site-packages\django\core\handlers\exception.py", line 55, in inner
    response = get_response(request)
  File "L:\oneSource_Live\venv\Lib\site-packages\django\core\handlers\base.py", line 197, in _get_response
    response = wrapped_callback(request, *callback_args, **callback_kwargs)
  File "L:\oneSource_Live\venv\Lib\site-packages\django\views\decorators\csrf.py", line 65, in _view_wrapper
    return view_func(request, *args, **kwargs)
  File "L:\oneSource_Live\oneSource\PRODUCTION\views.py", line 87, in search_equipment
    with connections['readonly_db'].cursor() as cursor:
         ~~~~~~~~~~~~~~~~~~~~~~~~~~~~~~~~~^^
  File "L:\oneSource_Live\venv\Lib\site-packages\django\utils\asyncio.py", line 26, in inner
    return func(*args, **kwargs)
  File "L:\oneSource_Live\venv\Lib\site-packages\django\db\backends\base\base.py", line 316, in cursor
    return self._cursor()
           ~~~~~~~~~~~~^^
  File "L:\oneSource_Live\venv\Lib\site-packages\mssql\base.py", line 261, in _cursor
    conn = super()._cursor()
  File "L:\oneSource_Live\venv\Lib\site-packages\django\db\backends\base\base.py", line 292, in _cursor
    self.ensure_connection()
    ~~~~~~~~~~~~~~~~~~~~~~^^
  File "L:\oneSource_Live\venv\Lib\site-packages\django\utils\asyncio.py", line 26, in inner
    return func(*args, **kwargs)
  File "L:\oneSource_Live\venv\Lib\site-packages\django\db\backends\base\base.py", line 274, in ensure_connection
    with self.wrap_database_errors:
         ^^^^^^^^^^^^^^^^^^^^^^^^^
  File "L:\oneSource_Live\venv\Lib\site-packages\django\db\utils.py", line 91, in __exit__
    raise dj_exc_value.with_traceback(traceback) from exc_value
  File "L:\oneSource_Live\venv\Lib\site-packages\django\db\backends\base\base.py", line 275, in ensure_connection
    self.connect()
    ~~~~~~~~~~~~^^
  File "L:\oneSource_Live\venv\Lib\site-packages\django\utils\asyncio.py", line 26, in inner
    return func(*args, **kwargs)
  File "L:\oneSource_Live\venv\Lib\site-packages\django\db\backends\base\base.py", line 256, in connect
    self.connection = self.get_new_connection(conn_params)
                      ~~~~~~~~~~~~~~~~~~~~~~~^^^^^^^^^^^^^
  File "L:\oneSource_Live\venv\Lib\site-packages\mssql\base.py", line 368, in get_new_connection
    conn = Database.connect(connstr, **args)
django.db.utils.OperationalError: ('08S01', '[08S01] [Microsoft][ODBC Driver 17 for SQL Server]Communication link failure (0) (SQLSetConnectAttr(SQL_ATTR_AUTOCOMMIT)); [08S01] [Microsoft][ODBC Driver 17 for SQL Server]The connection is broken and recovery is not possible. The client driver attempted to recover the connection one or more times and all attempts failed. Increase the value of ConnectRetryCount to increase the number of recovery attempts. (0)')
[2025-05-14 12:32:13,200] ERROR django.server "GET /search_equipment/?term=cr HTTP/1.1" 500 145
[2025-05-14 12:32:21,575] ERROR django.request Internal Server Error: /search_equipment/
Traceback (most recent call last):
  File "L:\oneSource_Live\venv\Lib\site-packages\django\db\backends\base\base.py", line 275, in ensure_connection
    self.connect()
    ~~~~~~~~~~~~^^
  File "L:\oneSource_Live\venv\Lib\site-packages\django\utils\asyncio.py", line 26, in inner
    return func(*args, **kwargs)
  File "L:\oneSource_Live\venv\Lib\site-packages\django\db\backends\base\base.py", line 256, in connect
    self.connection = self.get_new_connection(conn_params)
                      ~~~~~~~~~~~~~~~~~~~~~~~^^^^^^^^^^^^^
  File "L:\oneSource_Live\venv\Lib\site-packages\mssql\base.py", line 368, in get_new_connection
    conn = Database.connect(connstr, **args)
pyodbc.OperationalError: ('08S01', '[08S01] [Microsoft][ODBC Driver 17 for SQL Server]Communication link failure (0) (SQLSetConnectAttr(SQL_ATTR_AUTOCOMMIT)); [08S01] [Microsoft][ODBC Driver 17 for SQL Server]The connection is broken and recovery is not possible. The client driver attempted to recover the connection one or more times and all attempts failed. Increase the value of ConnectRetryCount to increase the number of recovery attempts. (0)')

The above exception was the direct cause of the following exception:

Traceback (most recent call last):
  File "L:\oneSource_Live\venv\Lib\site-packages\django\core\handlers\exception.py", line 55, in inner
    response = get_response(request)
  File "L:\oneSource_Live\venv\Lib\site-packages\django\core\handlers\base.py", line 197, in _get_response
    response = wrapped_callback(request, *callback_args, **callback_kwargs)
  File "L:\oneSource_Live\venv\Lib\site-packages\django\views\decorators\csrf.py", line 65, in _view_wrapper
    return view_func(request, *args, **kwargs)
  File "L:\oneSource_Live\oneSource\PRODUCTION\views.py", line 87, in search_equipment
    with connections['readonly_db'].cursor() as cursor:
         ~~~~~~~~~~~~~~~~~~~~~~~~~~~~~~~~~^^
  File "L:\oneSource_Live\venv\Lib\site-packages\django\utils\asyncio.py", line 26, in inner
    return func(*args, **kwargs)
  File "L:\oneSource_Live\venv\Lib\site-packages\django\db\backends\base\base.py", line 316, in cursor
    return self._cursor()
           ~~~~~~~~~~~~^^
  File "L:\oneSource_Live\venv\Lib\site-packages\mssql\base.py", line 261, in _cursor
    conn = super()._cursor()
  File "L:\oneSource_Live\venv\Lib\site-packages\django\db\backends\base\base.py", line 292, in _cursor
    self.ensure_connection()
    ~~~~~~~~~~~~~~~~~~~~~~^^
  File "L:\oneSource_Live\venv\Lib\site-packages\django\utils\asyncio.py", line 26, in inner
    return func(*args, **kwargs)
  File "L:\oneSource_Live\venv\Lib\site-packages\django\db\backends\base\base.py", line 274, in ensure_connection
    with self.wrap_database_errors:
         ^^^^^^^^^^^^^^^^^^^^^^^^^
  File "L:\oneSource_Live\venv\Lib\site-packages\django\db\utils.py", line 91, in __exit__
    raise dj_exc_value.with_traceback(traceback) from exc_value
  File "L:\oneSource_Live\venv\Lib\site-packages\django\db\backends\base\base.py", line 275, in ensure_connection
    self.connect()
    ~~~~~~~~~~~~^^
  File "L:\oneSource_Live\venv\Lib\site-packages\django\utils\asyncio.py", line 26, in inner
    return func(*args, **kwargs)
  File "L:\oneSource_Live\venv\Lib\site-packages\django\db\backends\base\base.py", line 256, in connect
    self.connection = self.get_new_connection(conn_params)
                      ~~~~~~~~~~~~~~~~~~~~~~~^^^^^^^^^^^^^
  File "L:\oneSource_Live\venv\Lib\site-packages\mssql\base.py", line 368, in get_new_connection
    conn = Database.connect(connstr, **args)
django.db.utils.OperationalError: ('08S01', '[08S01] [Microsoft][ODBC Driver 17 for SQL Server]Communication link failure (0) (SQLSetConnectAttr(SQL_ATTR_AUTOCOMMIT)); [08S01] [Microsoft][ODBC Driver 17 for SQL Server]The connection is broken and recovery is not possible. The client driver attempted to recover the connection one or more times and all attempts failed. Increase the value of ConnectRetryCount to increase the number of recovery attempts. (0)')
[2025-05-14 12:32:21,584] ERROR django.server "GET /search_equipment/ HTTP/1.1" 500 145
[2025-05-14 12:32:38,420] ERROR django.request Internal Server Error: /search_equipment/
Traceback (most recent call last):
  File "L:\oneSource_Live\venv\Lib\site-packages\django\db\backends\base\base.py", line 275, in ensure_connection
    self.connect()
    ~~~~~~~~~~~~^^
  File "L:\oneSource_Live\venv\Lib\site-packages\django\utils\asyncio.py", line 26, in inner
    return func(*args, **kwargs)
  File "L:\oneSource_Live\venv\Lib\site-packages\django\db\backends\base\base.py", line 256, in connect
    self.connection = self.get_new_connection(conn_params)
                      ~~~~~~~~~~~~~~~~~~~~~~~^^^^^^^^^^^^^
  File "L:\oneSource_Live\venv\Lib\site-packages\mssql\base.py", line 368, in get_new_connection
    conn = Database.connect(connstr, **args)
pyodbc.OperationalError: ('08S01', '[08S01] [Microsoft][ODBC Driver 17 for SQL Server]Communication link failure (0) (SQLSetConnectAttr(SQL_ATTR_AUTOCOMMIT)); [08S01] [Microsoft][ODBC Driver 17 for SQL Server]The connection is broken and recovery is not possible. The client driver attempted to recover the connection one or more times and all attempts failed. Increase the value of ConnectRetryCount to increase the number of recovery attempts. (0)')

The above exception was the direct cause of the following exception:

Traceback (most recent call last):
  File "L:\oneSource_Live\venv\Lib\site-packages\django\core\handlers\exception.py", line 55, in inner
    response = get_response(request)
  File "L:\oneSource_Live\venv\Lib\site-packages\django\core\handlers\base.py", line 197, in _get_response
    response = wrapped_callback(request, *callback_args, **callback_kwargs)
  File "L:\oneSource_Live\venv\Lib\site-packages\django\views\decorators\csrf.py", line 65, in _view_wrapper
    return view_func(request, *args, **kwargs)
  File "L:\oneSource_Live\oneSource\PRODUCTION\views.py", line 87, in search_equipment
    with connections['readonly_db'].cursor() as cursor:
         ~~~~~~~~~~~~~~~~~~~~~~~~~~~~~~~~~^^
  File "L:\oneSource_Live\venv\Lib\site-packages\django\utils\asyncio.py", line 26, in inner
    return func(*args, **kwargs)
  File "L:\oneSource_Live\venv\Lib\site-packages\django\db\backends\base\base.py", line 316, in cursor
    return self._cursor()
           ~~~~~~~~~~~~^^
  File "L:\oneSource_Live\venv\Lib\site-packages\mssql\base.py", line 261, in _cursor
    conn = super()._cursor()
  File "L:\oneSource_Live\venv\Lib\site-packages\django\db\backends\base\base.py", line 292, in _cursor
    self.ensure_connection()
    ~~~~~~~~~~~~~~~~~~~~~~^^
  File "L:\oneSource_Live\venv\Lib\site-packages\django\utils\asyncio.py", line 26, in inner
    return func(*args, **kwargs)
  File "L:\oneSource_Live\venv\Lib\site-packages\django\db\backends\base\base.py", line 274, in ensure_connection
    with self.wrap_database_errors:
         ^^^^^^^^^^^^^^^^^^^^^^^^^
  File "L:\oneSource_Live\venv\Lib\site-packages\django\db\utils.py", line 91, in __exit__
    raise dj_exc_value.with_traceback(traceback) from exc_value
  File "L:\oneSource_Live\venv\Lib\site-packages\django\db\backends\base\base.py", line 275, in ensure_connection
    self.connect()
    ~~~~~~~~~~~~^^
  File "L:\oneSource_Live\venv\Lib\site-packages\django\utils\asyncio.py", line 26, in inner
    return func(*args, **kwargs)
  File "L:\oneSource_Live\venv\Lib\site-packages\django\db\backends\base\base.py", line 256, in connect
    self.connection = self.get_new_connection(conn_params)
                      ~~~~~~~~~~~~~~~~~~~~~~~^^^^^^^^^^^^^
  File "L:\oneSource_Live\venv\Lib\site-packages\mssql\base.py", line 368, in get_new_connection
    conn = Database.connect(connstr, **args)
django.db.utils.OperationalError: ('08S01', '[08S01] [Microsoft][ODBC Driver 17 for SQL Server]Communication link failure (0) (SQLSetConnectAttr(SQL_ATTR_AUTOCOMMIT)); [08S01] [Microsoft][ODBC Driver 17 for SQL Server]The connection is broken and recovery is not possible. The client driver attempted to recover the connection one or more times and all attempts failed. Increase the value of ConnectRetryCount to increase the number of recovery attempts. (0)')
[2025-05-14 12:32:38,430] ERROR django.server "GET /search_equipment/?term=c HTTP/1.1" 500 145
[2025-05-14 12:32:38,760] ERROR django.request Internal Server Error: /search_equipment/
Traceback (most recent call last):
  File "L:\oneSource_Live\venv\Lib\site-packages\django\db\backends\base\base.py", line 275, in ensure_connection
    self.connect()
    ~~~~~~~~~~~~^^
  File "L:\oneSource_Live\venv\Lib\site-packages\django\utils\asyncio.py", line 26, in inner
    return func(*args, **kwargs)
  File "L:\oneSource_Live\venv\Lib\site-packages\django\db\backends\base\base.py", line 256, in connect
    self.connection = self.get_new_connection(conn_params)
                      ~~~~~~~~~~~~~~~~~~~~~~~^^^^^^^^^^^^^
  File "L:\oneSource_Live\venv\Lib\site-packages\mssql\base.py", line 368, in get_new_connection
    conn = Database.connect(connstr, **args)
pyodbc.OperationalError: ('08S01', '[08S01] [Microsoft][ODBC Driver 17 for SQL Server]Communication link failure (0) (SQLSetConnectAttr(SQL_ATTR_AUTOCOMMIT)); [08S01] [Microsoft][ODBC Driver 17 for SQL Server]The connection is broken and recovery is not possible. The client driver attempted to recover the connection one or more times and all attempts failed. Increase the value of ConnectRetryCount to increase the number of recovery attempts. (0)')

The above exception was the direct cause of the following exception:

Traceback (most recent call last):
  File "L:\oneSource_Live\venv\Lib\site-packages\django\core\handlers\exception.py", line 55, in inner
    response = get_response(request)
  File "L:\oneSource_Live\venv\Lib\site-packages\django\core\handlers\base.py", line 197, in _get_response
    response = wrapped_callback(request, *callback_args, **callback_kwargs)
  File "L:\oneSource_Live\venv\Lib\site-packages\django\views\decorators\csrf.py", line 65, in _view_wrapper
    return view_func(request, *args, **kwargs)
  File "L:\oneSource_Live\oneSource\PRODUCTION\views.py", line 87, in search_equipment
    with connections['readonly_db'].cursor() as cursor:
         ~~~~~~~~~~~~~~~~~~~~~~~~~~~~~~~~~^^
  File "L:\oneSource_Live\venv\Lib\site-packages\django\utils\asyncio.py", line 26, in inner
    return func(*args, **kwargs)
  File "L:\oneSource_Live\venv\Lib\site-packages\django\db\backends\base\base.py", line 316, in cursor
    return self._cursor()
           ~~~~~~~~~~~~^^
  File "L:\oneSource_Live\venv\Lib\site-packages\mssql\base.py", line 261, in _cursor
    conn = super()._cursor()
  File "L:\oneSource_Live\venv\Lib\site-packages\django\db\backends\base\base.py", line 292, in _cursor
    self.ensure_connection()
    ~~~~~~~~~~~~~~~~~~~~~~^^
  File "L:\oneSource_Live\venv\Lib\site-packages\django\utils\asyncio.py", line 26, in inner
    return func(*args, **kwargs)
  File "L:\oneSource_Live\venv\Lib\site-packages\django\db\backends\base\base.py", line 274, in ensure_connection
    with self.wrap_database_errors:
         ^^^^^^^^^^^^^^^^^^^^^^^^^
  File "L:\oneSource_Live\venv\Lib\site-packages\django\db\utils.py", line 91, in __exit__
    raise dj_exc_value.with_traceback(traceback) from exc_value
  File "L:\oneSource_Live\venv\Lib\site-packages\django\db\backends\base\base.py", line 275, in ensure_connection
    self.connect()
    ~~~~~~~~~~~~^^
  File "L:\oneSource_Live\venv\Lib\site-packages\django\utils\asyncio.py", line 26, in inner
    return func(*args, **kwargs)
  File "L:\oneSource_Live\venv\Lib\site-packages\django\db\backends\base\base.py", line 256, in connect
    self.connection = self.get_new_connection(conn_params)
                      ~~~~~~~~~~~~~~~~~~~~~~~^^^^^^^^^^^^^
  File "L:\oneSource_Live\venv\Lib\site-packages\mssql\base.py", line 368, in get_new_connection
    conn = Database.connect(connstr, **args)
django.db.utils.OperationalError: ('08S01', '[08S01] [Microsoft][ODBC Driver 17 for SQL Server]Communication link failure (0) (SQLSetConnectAttr(SQL_ATTR_AUTOCOMMIT)); [08S01] [Microsoft][ODBC Driver 17 for SQL Server]The connection is broken and recovery is not possible. The client driver attempted to recover the connection one or more times and all attempts failed. Increase the value of ConnectRetryCount to increase the number of recovery attempts. (0)')
[2025-05-14 12:32:38,769] ERROR django.server "GET /search_equipment/?term=cr HTTP/1.1" 500 145
[2025-05-14 12:33:18,157] ERROR django.request Internal Server Error: /search_equipment/
Traceback (most recent call last):
  File "L:\oneSource_Live\venv\Lib\site-packages\django\db\backends\base\base.py", line 275, in ensure_connection
    self.connect()
    ~~~~~~~~~~~~^^
  File "L:\oneSource_Live\venv\Lib\site-packages\django\utils\asyncio.py", line 26, in inner
    return func(*args, **kwargs)
  File "L:\oneSource_Live\venv\Lib\site-packages\django\db\backends\base\base.py", line 256, in connect
    self.connection = self.get_new_connection(conn_params)
                      ~~~~~~~~~~~~~~~~~~~~~~~^^^^^^^^^^^^^
  File "L:\oneSource_Live\venv\Lib\site-packages\mssql\base.py", line 368, in get_new_connection
    conn = Database.connect(connstr, **args)
pyodbc.OperationalError: ('08S01', '[08S01] [Microsoft][ODBC Driver 17 for SQL Server]Communication link failure (0) (SQLSetConnectAttr(SQL_ATTR_AUTOCOMMIT)); [08S01] [Microsoft][ODBC Driver 17 for SQL Server]The connection is broken and recovery is not possible. The client driver attempted to recover the connection one or more times and all attempts failed. Increase the value of ConnectRetryCount to increase the number of recovery attempts. (0)')

The above exception was the direct cause of the following exception:

Traceback (most recent call last):
  File "L:\oneSource_Live\venv\Lib\site-packages\django\core\handlers\exception.py", line 55, in inner
    response = get_response(request)
  File "L:\oneSource_Live\venv\Lib\site-packages\django\core\handlers\base.py", line 197, in _get_response
    response = wrapped_callback(request, *callback_args, **callback_kwargs)
  File "L:\oneSource_Live\venv\Lib\site-packages\django\views\decorators\csrf.py", line 65, in _view_wrapper
    return view_func(request, *args, **kwargs)
  File "L:\oneSource_Live\oneSource\PRODUCTION\views.py", line 87, in search_equipment
    with connections['readonly_db'].cursor() as cursor:
         ~~~~~~~~~~~~~~~~~~~~~~~~~~~~~~~~~^^
  File "L:\oneSource_Live\venv\Lib\site-packages\django\utils\asyncio.py", line 26, in inner
    return func(*args, **kwargs)
  File "L:\oneSource_Live\venv\Lib\site-packages\django\db\backends\base\base.py", line 316, in cursor
    return self._cursor()
           ~~~~~~~~~~~~^^
  File "L:\oneSource_Live\venv\Lib\site-packages\mssql\base.py", line 261, in _cursor
    conn = super()._cursor()
  File "L:\oneSource_Live\venv\Lib\site-packages\django\db\backends\base\base.py", line 292, in _cursor
    self.ensure_connection()
    ~~~~~~~~~~~~~~~~~~~~~~^^
  File "L:\oneSource_Live\venv\Lib\site-packages\django\utils\asyncio.py", line 26, in inner
    return func(*args, **kwargs)
  File "L:\oneSource_Live\venv\Lib\site-packages\django\db\backends\base\base.py", line 274, in ensure_connection
    with self.wrap_database_errors:
         ^^^^^^^^^^^^^^^^^^^^^^^^^
  File "L:\oneSource_Live\venv\Lib\site-packages\django\db\utils.py", line 91, in __exit__
    raise dj_exc_value.with_traceback(traceback) from exc_value
  File "L:\oneSource_Live\venv\Lib\site-packages\django\db\backends\base\base.py", line 275, in ensure_connection
    self.connect()
    ~~~~~~~~~~~~^^
  File "L:\oneSource_Live\venv\Lib\site-packages\django\utils\asyncio.py", line 26, in inner
    return func(*args, **kwargs)
  File "L:\oneSource_Live\venv\Lib\site-packages\django\db\backends\base\base.py", line 256, in connect
    self.connection = self.get_new_connection(conn_params)
                      ~~~~~~~~~~~~~~~~~~~~~~~^^^^^^^^^^^^^
  File "L:\oneSource_Live\venv\Lib\site-packages\mssql\base.py", line 368, in get_new_connection
    conn = Database.connect(connstr, **args)
django.db.utils.OperationalError: ('08S01', '[08S01] [Microsoft][ODBC Driver 17 for SQL Server]Communication link failure (0) (SQLSetConnectAttr(SQL_ATTR_AUTOCOMMIT)); [08S01] [Microsoft][ODBC Driver 17 for SQL Server]The connection is broken and recovery is not possible. The client driver attempted to recover the connection one or more times and all attempts failed. Increase the value of ConnectRetryCount to increase the number of recovery attempts. (0)')
[2025-05-14 12:33:18,166] ERROR django.server "GET /search_equipment/ HTTP/1.1" 500 145
[2025-05-14 12:33:32,242] ERROR django.request Internal Server Error: /search_equipment/
Traceback (most recent call last):
  File "L:\oneSource_Live\venv\Lib\site-packages\django\db\backends\base\base.py", line 275, in ensure_connection
    self.connect()
    ~~~~~~~~~~~~^^
  File "L:\oneSource_Live\venv\Lib\site-packages\django\utils\asyncio.py", line 26, in inner
    return func(*args, **kwargs)
  File "L:\oneSource_Live\venv\Lib\site-packages\django\db\backends\base\base.py", line 256, in connect
    self.connection = self.get_new_connection(conn_params)
                      ~~~~~~~~~~~~~~~~~~~~~~~^^^^^^^^^^^^^
  File "L:\oneSource_Live\venv\Lib\site-packages\mssql\base.py", line 368, in get_new_connection
    conn = Database.connect(connstr, **args)
pyodbc.OperationalError: ('08S01', '[08S01] [Microsoft][ODBC Driver 17 for SQL Server]Communication link failure (0) (SQLSetConnectAttr(SQL_ATTR_AUTOCOMMIT)); [08S01] [Microsoft][ODBC Driver 17 for SQL Server]The connection is broken and recovery is not possible. The client driver attempted to recover the connection one or more times and all attempts failed. Increase the value of ConnectRetryCount to increase the number of recovery attempts. (0)')

The above exception was the direct cause of the following exception:

Traceback (most recent call last):
  File "L:\oneSource_Live\venv\Lib\site-packages\django\core\handlers\exception.py", line 55, in inner
    response = get_response(request)
  File "L:\oneSource_Live\venv\Lib\site-packages\django\core\handlers\base.py", line 197, in _get_response
    response = wrapped_callback(request, *callback_args, **callback_kwargs)
  File "L:\oneSource_Live\venv\Lib\site-packages\django\views\decorators\csrf.py", line 65, in _view_wrapper
    return view_func(request, *args, **kwargs)
  File "L:\oneSource_Live\oneSource\PRODUCTION\views.py", line 87, in search_equipment
    with connections['readonly_db'].cursor() as cursor:
         ~~~~~~~~~~~~~~~~~~~~~~~~~~~~~~~~~^^
  File "L:\oneSource_Live\venv\Lib\site-packages\django\utils\asyncio.py", line 26, in inner
    return func(*args, **kwargs)
  File "L:\oneSource_Live\venv\Lib\site-packages\django\db\backends\base\base.py", line 316, in cursor
    return self._cursor()
           ~~~~~~~~~~~~^^
  File "L:\oneSource_Live\venv\Lib\site-packages\mssql\base.py", line 261, in _cursor
    conn = super()._cursor()
  File "L:\oneSource_Live\venv\Lib\site-packages\django\db\backends\base\base.py", line 292, in _cursor
    self.ensure_connection()
    ~~~~~~~~~~~~~~~~~~~~~~^^
  File "L:\oneSource_Live\venv\Lib\site-packages\django\utils\asyncio.py", line 26, in inner
    return func(*args, **kwargs)
  File "L:\oneSource_Live\venv\Lib\site-packages\django\db\backends\base\base.py", line 274, in ensure_connection
    with self.wrap_database_errors:
         ^^^^^^^^^^^^^^^^^^^^^^^^^
  File "L:\oneSource_Live\venv\Lib\site-packages\django\db\utils.py", line 91, in __exit__
    raise dj_exc_value.with_traceback(traceback) from exc_value
  File "L:\oneSource_Live\venv\Lib\site-packages\django\db\backends\base\base.py", line 275, in ensure_connection
    self.connect()
    ~~~~~~~~~~~~^^
  File "L:\oneSource_Live\venv\Lib\site-packages\django\utils\asyncio.py", line 26, in inner
    return func(*args, **kwargs)
  File "L:\oneSource_Live\venv\Lib\site-packages\django\db\backends\base\base.py", line 256, in connect
    self.connection = self.get_new_connection(conn_params)
                      ~~~~~~~~~~~~~~~~~~~~~~~^^^^^^^^^^^^^
  File "L:\oneSource_Live\venv\Lib\site-packages\mssql\base.py", line 368, in get_new_connection
    conn = Database.connect(connstr, **args)
django.db.utils.OperationalError: ('08S01', '[08S01] [Microsoft][ODBC Driver 17 for SQL Server]Communication link failure (0) (SQLSetConnectAttr(SQL_ATTR_AUTOCOMMIT)); [08S01] [Microsoft][ODBC Driver 17 for SQL Server]The connection is broken and recovery is not possible. The client driver attempted to recover the connection one or more times and all attempts failed. Increase the value of ConnectRetryCount to increase the number of recovery attempts. (0)')
[2025-05-14 12:33:32,250] ERROR django.server "GET /search_equipment/ HTTP/1.1" 500 145
